Workbook

Sheet README
A1: Oil – Global Supply & Demand with scenario analysis
A2: Updated October 14, 2026 · data: EIA Short-Term Energy Outlook October 2026 (tables 2 and 3a), IEA OMR October 2026
A4: Sheets
A5: Scenarios | B5: CONTROL PANEL: pick the active scenario, edit levers and probabilities, compare scenarios, sensitivity grid
A6: Balance | B6: Quarterly balance 25Q1–27Q4: OPEC/non-OPEC supply, OECD/non-OECD demand, balance, inventories, price – EIA base + active scenario
A7: EIA_Data | B7: Raw EIA STEO Oct-2026 data copied from the official tables (no estimates)
A8: Agency_Check | B8: EIA vs IEA vs OPEC on annual figures
A9: OPEC+ | B9: Production by country Aug/Sep 2026 vs targets and capacity (IEA)
A10: Gulf_Flows | B10: Gulf exports, Hormuz, bypass routes, refined products (IEA, Kpler)
A11: US_Weekly | B11: Weekly EIA inventories vs consensus and Hurricane Isaias
A12: Catalysts | B12: Event calendar and risks
A15: Legend
A16: Blue text | B16: Hardcoded input (from an official source, cited alongside)
A17: Yellow fill | B17: Scenario lever or model assumption: this is where you run your what-ifs
A18: Black text | B18: Formula
A19: Green text | B19: Link to another sheet
A20: Cream fill | B20: EIA forecast quarter (26Q4 onward; 26Q3 partly estimated)
A22: How to run scenarios | B22: 1) Scenarios!C4: pick the scenario → Balance updates. 2) Edit the yellow levers (mb/d per quarter, risk premium in $). 3) Read the comparison table and the probability-weighted average. 4) Use the grid for quick supply and demand shocks.
A23: Example | B23: 'Custom' scenario: enter −1.5 on the Gulf/Hormuz lever in 26Q4 and +$8 premium → see implied Brent, WTI and the quarter's balance.
A24: Price model | B24: Scenario price = EIA price − elasticity × (OECD stock change vs base)/100 + risk premium. The elasticity (~$6.7 per 100 mb of OECD stocks) is implied by EIA's own 26Q4→27Q4 forecast; editable in Scenarios.
A26: Caveat | B26: Scenario levers and probabilities are model assumptions, not data. Not investment advice.
A28: Sources
A29: EIA STEO table 3a | B29: https://www.eia.gov/outlooks/steo/tables/pdf/3atab.pdf
A30: EIA STEO table 2 | B30: https://www.eia.gov/outlooks/steo/tables/pdf/2tab.pdf
A31: EIA STEO text | B31: https://www.eia.gov/outlooks/steo/report/global_oil.php
A32: IEA OMR Oct-2026 | B32: https://www.iea.org/reports/oil-market-report-october-2026
A33: OPEC MOMR lug-2026 (Argus) | B33: https://www.argusmedia.com/en/news-and-insights/latest-market-news/2851347-opec-downgrades-2026-oil-demand-forecast
A34: EIA WPSR | B34: https://www.eia.gov/petroleum/supply/weekly/
A35: Trading Economics | B35: https://tradingeconomics.com/united-states/crude-oil-stocks-change
A36: Investing.com API | B36: https://www.investing.com/economic-calendar/api-weekly-crude-stock-656
A37: Kpler via Al Jazeera | B37: https://www.aljazeera.com/news/2026/9/30/economic-war-is-iran-losing-its-leverage-over-the-strait-of-hormuz
A38: Isaias – Reuters/BOE | B38: https://boereport.com/2026/10/09/us-gulf-producers-shut-in-more-oil-and-gas-as-isaias-nears-landfall/
A39: World Oil Monitor (WTI) | B39: https://worldoilmonitor.com/wti

Sheet Scenarios
A1: Scenario analysis – control panel
A2: Levers in mb/d (positive = more supply or more demand) applied 26Q4–27Q4 on top of the EIA base · risk premium in $/bbl on Brent
A4: Active scenario | C4: EIA Base | F4: ← pick from the menu: updates the Balance sheet
A6: Price model parameters
A7: Elasticity: $/bbl of Brent per 100 mb of OECD stocks | C7: =-(EIA_Data!N$40-EIA_Data!J$40)/(EIA_Data!N$36-EIA_Data!J$36)*100 | D7: Derived from the EIA forecast: Brent and OECD stocks from 26Q4 to 27Q4
A8: Override elasticity (leave blank to use EIA's) | D8: E.g. 10 if you think the market reacts more to inventories
A9: Elasticity in use | C9: =IF(C8="",C7,C8)
A10: OECD share of world inventory change | C10: =(EIA_Data!Q$32+EIA_Data!Q$33)/EIA_Data!Q$31 | D10: Derived from EIA 2027 withdrawals: the part of stock changes landing in OECD countries
A11: Brent–WTI spread used | C11: from EIA, by quarter | D11: Scenario WTI = scenario Brent − EIA spread for the same quarter
A13: Levers by scenario (yellow cells are editable)
A14: Scenario | B14: Lever | C14: 26Q4 | D14: 27Q1 | E14: 27Q2 | F14: 27Q3 | G14: 27Q4 | H14: Type | I14: Probability | J14: Rationale
A15: EIA Base | B15: Gulf / Hormuz | C15: 0 | D15: 0 | E15: 0 | F15: 0 | G15: 0 | H15: Supply | I15: 0.45 | J15: EIA forecast as published
A16: EIA Base | B16: Russia | C16: 0 | D16: 0 | E16: 0 | F16: 0 | G16: 0 | H16: Supply
A17: EIA Base | B17: Hurricanes / US | C17: 0 | D17: 0 | E17: 0 | F17: 0 | G17: 0 | H17: Supply
A18: EIA Base | B18: Strategic stocks (SPR/IEA) | C18: 0 | D18: 0 | E18: 0 | F18: 0 | G18: 0 | H18: Supply
A19: EIA Base | B19: OPEC+ policy | C19: 0 | D19: 0 | E19: 0 | F19: 0 | G19: 0 | H19: Supply
A20: EIA Base | B20: Demand shock | C20: 0 | D20: 0 | E20: 0 | F20: 0 | G20: 0 | H20: Demand
A21: EIA Base | B21: Risk premium ($/bbl) | C21: 0 | D21: 0 | E21: 0 | F21: 0 | G21: 0 | H21: Price
A22: Gulf Escalation | B22: Gulf / Hormuz | C22: -2 | D22: -1.5 | E22: -0.8 | F22: -0.3 | G22: 0 | H22: Supply | I22: 0.2 | J22: New attacks on Saudi infrastructure and tankers: −2 mb/d then recovery; stock release; more demand destruction
A23: Gulf Escalation | B23: Russia | C23: 0 | D23: 0 | E23: 0 | F23: 0 | G23: 0 | H23: Supply
A24: Gulf Escalation | B24: Hurricanes / US | C24: 0 | D24: 0 | E24: 0 | F24: 0 | G24: 0 | H24: Supply
A25: Gulf Escalation | B25: Strategic stocks (SPR/IEA) | C25: 0.5 | D25: 0.3 | E25: 0 | F25: 0 | G25: 0 | H25: Supply
A26: Gulf Escalation | B26: OPEC+ policy | C26: 0 | D26: 0 | E26: 0 | F26: 0 | G26: 0 | H26: Supply
A27: Gulf Escalation | B27: Demand shock | C27: -0.4 | D27: -0.4 | E27: -0.2 | F27: 0 | G27: 0 | H27: Demand
A28: Gulf Escalation | B28: Risk premium ($/bbl) | C28: 10 | D28: 8 | E28: 5 | F28: 2 | G28: 0 | H28: Price
A29: Iran Deal / Hormuz Reopened | B29: Gulf / Hormuz | C29: 1 | D29: 1.5 | E29: 1 | F29: 0.5 | G29: 0.3 | H29: Supply | I29: 0.15 | J29: US–Iran deal: faster flows and the geopolitical premium (~$20 est.) deflates
A30: Iran Deal / Hormuz Reopened | B30: Russia | C30: 0 | D30: 0 | E30: 0 | F30: 0 | G30: 0 | H30: Supply
A31: Iran Deal / Hormuz Reopened | B31: Hurricanes / US | C31: 0 | D31: 0 | E31: 0 | F31: 0 | G31: 0 | H31: Supply
A32: Iran Deal / Hormuz Reopened | B32: Strategic stocks (SPR/IEA) | C32: 0 | D32: 0 | E32: 0 | F32: 0 | G32: 0 | H32: Supply
A33: Iran Deal / Hormuz Reopened | B33: OPEC+ policy | C33: 0 | D33: 0 | E33: 0 | F33: 0 | G33: 0 | H33: Supply
A34: Iran Deal / Hormuz Reopened | B34: Demand shock | C34: 0.2 | D34: 0.3 | E34: 0.3 | F34: 0.2 | G34: 0.1 | H34: Demand
A35: Iran Deal / Hormuz Reopened | B35: Risk premium ($/bbl) | C35: -12 | D35: -10 | E35: -6 | F35: -3 | G35: 0 | H35: Price
A36: Global Recession | B36: Gulf / Hormuz | C36: 0 | D36: 0 | E36: 0 | F36: 0 | G36: 0 | H36: Supply | I36: 0.1 | J36: High prices and inflation slow the economy: demand falls, OPEC+ cuts
A37: Global Recession | B37: Russia | C37: 0 | D37: 0 | E37: 0 | F37: 0 | G37: 0 | H37: Supply
A38: Global Recession | B38: Hurricanes / US | C38: 0 | D38: 0 | E38: 0 | F38: 0 | G38: 0 | H38: Supply
A39: Global Recession | B39: Strategic stocks (SPR/IEA) | C39: 0 | D39: 0 | E39: 0 | F39: 0 | G39: 0 | H39: Supply
A40: Global Recession | B40: OPEC+ policy | C40: -0.3 | D40: -0.5 | E40: -0.5 | F40: -0.5 | G40: -0.5 | H40: Supply
A41: Global Recession | B41: Demand shock | C41: -1 | D41: -1.5 | E41: -1.5 | F41: -1 | G41: -0.8 | H41: Demand
A42: Global Recession | B42: Risk premium ($/bbl) | C42: 0 | D42: 0 | E42: 0 | F42: 0 | G42: 0 | H42: Price
A43: Russia & Diesel Stress | B43: Gulf / Hormuz | C43: 0 | D43: 0 | E43: 0 | F43: 0 | G43: 0 | H43: Supply | I43: 0.1 | J43: Ukrainian strikes on refineries and the energy truce collapses
...

Sheet Balance
A1: Global oil balance – EIA base and active scenario
A2: mb/d unless stated · source EIA STEO Oct-2026 · active scenario: | H2: =Scenarios!C4
A4: Line item | B4: Unit | C4: 25Q1 | D4: 25Q2 | E4: 25Q3 | F4: 25Q4 | G4: 26Q1 | H4: 26Q2 | I4: 26Q3 | J4: 26Q4 | K4: 27Q1 | L4: 27Q2 | M4: 27Q3 | N4: 27Q4 | O4: 2025 | P4: 2026 | Q4: 2027 | R4: Notes
A5: SUPPLY
A6: OPEC crude | B6: mb/d | C6: =EIA_Data!C$10 | D6: =EIA_Data!D$10 | E6: =EIA_Data!E$10 | F6: =EIA_Data!F$10 | G6: =EIA_Data!G$10 | H6: =EIA_Data!H$10 | I6: =EIA_Data!I$10 | J6: =EIA_Data!J$10 | ... Q6: =EIA_Data!Q$10
A7: OPEC other liquids | B7: mb/d | C7: =EIA_Data!C$11 | D7: =EIA_Data!D$11 | E7: =EIA_Data!E$11 | F7: =EIA_Data!F$11 | G7: =EIA_Data!G$11 | H7: =EIA_Data!H$11 | I7: =EIA_Data!I$11 | J7: =EIA_Data!J$11 | ... Q7: =EIA_Data!Q$11
A8: Non-OPEC crude | B8: mb/d | C8: =EIA_Data!C$13 | D8: =EIA_Data!D$13 | E8: =EIA_Data!E$13 | F8: =EIA_Data!F$13 | G8: =EIA_Data!G$13 | H8: =EIA_Data!H$13 | I8: =EIA_Data!I$13 | J8: =EIA_Data!J$13 | ... Q8: =EIA_Data!Q$13
A9: Non-OPEC other liquids | B9: mb/d | C9: =EIA_Data!C$14 | D9: =EIA_Data!D$14 | E9: =EIA_Data!E$14 | F9: =EIA_Data!F$14 | G9: =EIA_Data!G$14 | H9: =EIA_Data!H$14 | I9: =EIA_Data!I$14 | J9: =EIA_Data!J$14 | ... Q9: =EIA_Data!Q$14
A10: World supply (EIA base) | B10: mb/d | C10: =SUM(C6:C9) | D10: =SUM(D6:D9) | E10: =SUM(E6:E9) | F10: =SUM(F6:F9) | G10: =SUM(G6:G9) | H10: =SUM(H6:H9) | I10: =SUM(I6:I9) | J10: =SUM(J6:J9) | ... Q10: =SUM(Q6:Q9)
A11: Change y/y | B11: mb/d | G11: =G10-C10 | H11: =H10-D10 | I11: =I10-E10 | J11: =J10-F10 | K11: =K10-G10 | L11: =L10-H10 | M11: =M10-I10 | N11: =N10-J10 | P11: =P10-O10 | Q11: =Q10-P10
A12: OPEC share of supply | B12: % | C12: =(C6+C7)/C10 | D12: =(D6+D7)/D10 | E12: =(E6+E7)/E10 | F12: =(F6+F7)/F10 | G12: =(G6+G7)/G10 | H12: =(H6+H7)/H10 | I12: =(I6+I7)/I10 | J12: =(J6+J7)/J10 | ... Q12: =(Q6+Q7)/Q10
A14: DEMAND
A15: United States | B15: mb/d | C15: =EIA_Data!C$18 | D15: =EIA_Data!D$18 | E15: =EIA_Data!E$18 | F15: =EIA_Data!F$18 | G15: =EIA_Data!G$18 | H15: =EIA_Data!H$18 | I15: =EIA_Data!I$18 | J15: =EIA_Data!J$18 | ... Q15: =EIA_Data!Q$18
A16: OECD Europe | B16: mb/d | C16: =EIA_Data!C$19 | D16: =EIA_Data!D$19 | E16: =EIA_Data!E$19 | F16: =EIA_Data!F$19 | G16: =EIA_Data!G$19 | H16: =EIA_Data!H$19 | I16: =EIA_Data!I$19 | J16: =EIA_Data!J$19 | ... Q16: =EIA_Data!Q$19
A17: OECD total | B17: mb/d | C17: =EIA_Data!C$17 | D17: =EIA_Data!D$17 | E17: =EIA_Data!E$17 | F17: =EIA_Data!F$17 | G17: =EIA_Data!G$17 | H17: =EIA_Data!H$17 | I17: =EIA_Data!I$17 | J17: =EIA_Data!J$17 | ... Q17: =EIA_Data!Q$17
A18: China | B18: mb/d | C18: =EIA_Data!C$25 | D18: =EIA_Data!D$25 | E18: =EIA_Data!E$25 | F18: =EIA_Data!F$25 | G18: =EIA_Data!G$25 | H18: =EIA_Data!H$25 | I18: =EIA_Data!I$25 | J18: =EIA_Data!J$25 | ... Q18: =EIA_Data!Q$25
A19: Other Asia (incl. India) | B19: mb/d | C19: =EIA_Data!C$26 | D19: =EIA_Data!D$26 | E19: =EIA_Data!E$26 | F19: =EIA_Data!F$26 | G19: =EIA_Data!G$26 | H19: =EIA_Data!H$26 | I19: =EIA_Data!I$26 | J19: =EIA_Data!J$26 | ... Q19: =EIA_Data!Q$26
A20: Non-OECD total | B20: mb/d | C20: =EIA_Data!C$24 | D20: =EIA_Data!D$24 | E20: =EIA_Data!E$24 | F20: =EIA_Data!F$24 | G20: =EIA_Data!G$24 | H20: =EIA_Data!H$24 | I20: =EIA_Data!I$24 | J20: =EIA_Data!J$24 | ... Q20: =EIA_Data!Q$24
A21: World demand (EIA base) | B21: mb/d | C21: =C17+C20 | D21: =D17+D20 | E21: =E17+E20 | F21: =F17+F20 | G21: =G17+G20 | H21: =H17+H20 | I21: =I17+I20 | J21: =J17+J20 | ... Q21: =Q17+Q20
A22: Change y/y | B22: mb/d | G22: =G21-C21 | H22: =H21-D21 | I22: =I21-E21 | J22: =J21-F21 | K22: =K21-G21 | L22: =L21-H21 | M22: =M21-I21 | N22: =N21-J21 | P22: =P21-O21 | Q22: =Q21-P21
A24: ACTIVE SCENARIO
A25: Supply adjustment | B25: mb/d | C25: 0 | D25: 0 | E25: 0 | F25: 0 | G25: 0 | H25: 0 | I25: 0 | J25: =Scenarios!C$61 | K25: =Scenarios!D$61 | L25: =Scenarios!E$61 | M25: =Scenarios!F$61 | N25: =Scenarios!G$61 | O25: =AVERAGE(C25:F25) | P25: =AVERAGE(G25:J25) | Q25: =AVERAGE(K25:N25) | R25: From the Scenarios sheet: applies from 26Q4
A26: Demand adjustment | B26: mb/d | C26: 0 | D26: 0 | E26: 0 | F26: 0 | G26: 0 | H26: 0 | I26: 0 | J26: =Scenarios!C$62 | K26: =Scenarios!D$62 | L26: =Scenarios!E$62 | M26: =Scenarios!F$62 | N26: =Scenarios!G$62 | O26: =AVERAGE(C26:F26) | P26: =AVERAGE(G26:J26) | Q26: =AVERAGE(K26:N26)
A27: Scenario supply | B27: mb/d | C27: =C10+C25 | D27: =D10+D25 | E27: =E10+E25 | F27: =F10+F25 | G27: =G10+G25 | H27: =H10+H25 | I27: =I10+I25 | J27: =J10+J25 | ... Q27: =Q10+Q25
A28: Scenario demand | B28: mb/d | C28: =C21+C26 | D28: =D21+D26 | E28: =E21+E26 | F28: =F21+F26 | G28: =G21+G26 | H28: =H21+H26 | I28: =I21+I26 | J28: =J21+J26 | ... Q28: =Q21+Q26
A30: BALANCE AND INVENTORIES
A31: EIA base balance (supply − demand) | B31: mb/d | C31: =C10-C21 | D31: =D10-D21 | E31: =E10-E21 | F31: =F10-F21 | G31: =G10-G21 | H31: =H10-H21 | I31: =I10-I21 | J31: =J10-J21 | ... Q31: =Q10-Q21
A32: Scenario balance | B32: mb/d | C32: =C27-C28 | D32: =D27-D28 | E32: =E27-E28 | F32: =F27-F28 | G32: =G27-G28 | H32: =H27-H28 | I32: =I27-I28 | J32: =J27-J28 | ... Q32: =Q27-Q28 | R32: Negative = deficit: the world consumes more than it produces
A33: Days in period | B33: days | C33: 90 | D33: 91 | E33: 92 | F33: 92 | G33: 90 | H33: 91 | I33: 92 | J33: 92 | K33: 90 | L33: 91 | M33: 92 | N33: 92 | O33: 365 | P33: 365 | Q33: 365
A34: World inventory change (scenario) | B34: mb | C34: =C32*C33 | D34: =D32*D33 | E34: =E32*E33 | F34: =F32*F33 | G34: =G32*G33 | H34: =H32*H33 | I34: =I32*I33 | J34: =J32*J33 | ... Q34: =Q32*Q33
A35: Cumulative world stock gap vs base | B35: mb | C35: =(C32-C31)*C33 | D35: =C35+(D32-D31)*D33 | E35: =D35+(E32-E31)*E33 | F35: =E35+(F32-F31)*F33 | G35: =F35+(G32-G31)*G33 | H35: =G35+(H32-H31)*H33 | I35: =H35+(I32-I31)*I33 | J35: =I35+(J32-J31)*J33 | K35: =J35+(K32-K31)*K33 | ... N35: =M35+(N32-N31)*N33 | O35: =F35 | P35: =J35 | Q35: =N35
A36: OECD commercial stocks – EIA base | B36: mb | C36: =EIA_Data!C$36 | D36: =EIA_Data!D$36 | E36: =EIA_Data!E$36 | F36: =EIA_Data!F$36 | G36: =EIA_Data!G$36 | H36: =EIA_Data!H$36 | I36: =EIA_Data!I$36 | J36: =EIA_Data!J$36 | ... Q36: =EIA_Data!Q$36
A37: OECD commercial stocks – scenario | B37: mb | C37: =C36+C35*Scenarios!C$10 | D37: =D36+D35*Scenarios!C$10 | E37: =E36+E35*Scenarios!C$10 | F37: =F36+F35*Scenarios!C$10 | G37: =G36+G35*Scenarios!C$10 | H37: =H36+H35*Scenarios!C$10 | I37: =I36+I35*Scenarios!C$10 | J37: =J36+J35*Scenarios!C$10 | K37: =K36+K35*Scenarios!C$10 | L37: =L36+L35*Scenarios!C$10 | M37: =M36+M35*Scenarios!C$10 | N37: =N36+N35*Scenarios!C$10 | O37: =O36+O35*Scenarios!C$10 | P37: =P36+P35*Scenarios!C$10 | Q37: =Q36+Q35*Scenarios!C$10 | R37: EIA base + OECD share of the cumulative gap
A38: Read | C38: =IF(C32<0,"Deficit","Surplus") | D38: =IF(D32<0,"Deficit","Surplus") | E38: =IF(E32<0,"Deficit","Surplus") | F38: =IF(F32<0,"Deficit","Surplus") | G38: =IF(G32<0,"Deficit","Surplus") | H38: =IF(H32<0,"Deficit","Surplus") | I38: =IF(I32<0,"Deficit","Surplus") | J38: =IF(J32<0,"Deficit","Surplus") | ... Q38: =IF(Q32<0,"Deficit","Surplus")
A40: PRICES
A41: Brent – EIA forecast | B41: $/bbl | C41: =EIA_Data!C$40 | D41: =EIA_Data!D$40 | E41: =EIA_Data!E$40 | F41: =EIA_Data!F$40 | G41: =EIA_Data!G$40 | H41: =EIA_Data!H$40 | I41: =EIA_Data!I$40 | J41: =EIA_Data!J$40 | ... Q41: =EIA_Data!Q$40
A42: WTI – EIA forecast | B42: $/bbl | C42: =EIA_Data!C$41 | D42: =EIA_Data!D$41 | E42: =EIA_Data!E$41 | F42: =EIA_Data!F$41 | G42: =EIA_Data!G$41 | H42: =EIA_Data!H$41 | I42: =EIA_Data!I$41 | J42: =EIA_Data!J$41 | ... Q42: =EIA_Data!Q$41
A43: Scenario risk premium | B43: $/bbl | C43: 0 | D43: 0 | E43: 0 | F43: 0 | G43: 0 | H43: 0 | I43: 0 | J43: =Scenarios!C$63 | K43: =Scenarios!D$63 | L43: =Scenarios!E$63 | M43: =Scenarios!F$63 | N43: =Scenarios!G$63 | O43: =AVERAGE(C43:F43) | P43: =AVERAGE(G43:J43) | Q43: =AVERAGE(K43:N43)
A44: Brent – scenario | B44: $/bbl | C44: =C41-Scenarios!C$9*(C37-C36)/100+C43 | D44: =D41-Scenarios!C$9*(D37-D36)/100+D43 | E44: =E41-Scenarios!C$9*(E37-E36)/100+E43 | F44: =F41-Scenarios!C$9*(F37-F36)/100+F43 | G44: =G41-Scenarios!C$9*(G37-G36)/100+G43 | H44: =H41-Scenarios!C$9*(H37-H36)/100+H43 | I44: =I41-Scenarios!C$9*(I37-I36)/100+I43 | J44: =J41-Scenarios!C$9*(J37-J36)/100+J43 | K44: =K41-Scenarios!C$9*(K37-K36)/100+K43 | L44: =L41-Scenarios!C$9*(L37-L36)/100+L43 | M44: =M41-Scenarios!C$9*(M37-M36)/100+M43 | N44: =N41-Scenarios!C$9*(N37-N36)/100+N43 | O44: =O41+AVERAGE(C44:F44)-AVERAGE(C41:F41) | P44: =P41+AVERAGE(G44:J44)-AVERAGE(G41:J41) | Q44: =Q41+AVERAGE(K44:N44)-AVERAGE(K41:N41) | R44: Model: EIA base − elasticity × OECD stock gap + premium (see Scenarios)
A45: WTI – scenario | B45: $/bbl | C45: =C44-(C41-C42) | D45: =D44-(D41-D42) | E45: =E44-(E41-E42) | F45: =F44-(F41-F42) | G45: =G44-(G41-G42) | H45: =H44-(H41-H42) | I45: =I44-(I41-I42) | J45: =J44-(J41-J42) | ... N45: =N44-(N41-N42) | O45: =O42+AVERAGE(C45:F45)-AVERAGE(C42:F42) | P45: =P42+AVERAGE(G45:J45)-AVERAGE(G42:J42) | Q45: =Q42+AVERAGE(K45:N45)-AVERAGE(K42:N42)
...

Sheet EIA_Data
A1: EIA Short-Term Energy Outlook – October 2026 (official data)
A2: Copied from EIA tables 3a and 2 (model completed Oct 1, 2026). mb/d unless stated. Cream fill = forecast.
A4: Series | B4: Unit | C4: 25Q1 | D4: 25Q2 | E4: 25Q3 | F4: 25Q4 | G4: 26Q1 | H4: 26Q2 | I4: 26Q3 | J4: 26Q4 | K4: 27Q1 | L4: 27Q2 | M4: 27Q3 | N4: 27Q4 | O4: 2025 | P4: 2026 | Q4: 2027 | R4: Source
A5: PRODUCTION
A6: World production | B6: mb/d | C6: 103.58 | D6: 105.19 | E6: 107.9 | F6: 108.42 | G6: 103.66 | H6: 96.49 | I6: 101.25 | J6: 102.97 | K6: 106.11 | L6: 109.55 | M6: 110.92 | N6: 111.55 | O6: 106.29 | P6: 101.09 | Q6: 109.55 | R6: EIA STEO Oct-2026, table 3a
A7: Crude oil | B7: mb/d | C7: 77.25 | D7: 78.03 | E7: 80 | F7: 80.69 | G7: 77.33 | H7: 71.57 | I7: 75.69 | J7: 77.02 | K7: 79.6 | L7: 81.3 | M7: 82.2 | N7: 82.86 | O7: 79 | P7: 75.4 | Q7: 81.5 | R7: EIA STEO Oct-2026, table 3a
A8: Other liquids | B8: mb/d | C8: 26.33 | D8: 27.16 | E8: 27.9 | F8: 27.73 | G8: 26.33 | H8: 24.92 | I8: 25.56 | J8: 25.95 | K8: 26.51 | L8: 28.25 | M8: 28.72 | N8: 28.69 | O8: 27.29 | P8: 25.69 | Q8: 28.05 | R8: EIA STEO Oct-2026, table 3a
A9: OPEC total | B9: mb/d | C9: 28.67 | D9: 29.11 | E9: 29.53 | F9: 30.01 | G9: 27.46 | H9: 20.35 | I9: 23.58 | J9: 24.38 | K9: 26.87 | L9: 29.49 | M9: 30.1 | N9: 30.21 | O9: 29.33 | P9: 23.93 | Q9: 29.18 | R9: EIA STEO Oct-2026, table 3a
A10: OPEC crude | B10: mb/d | C10: 24.04 | D10: 24.46 | E10: 24.82 | F10: 25.19 | G10: 23.08 | H10: 17.3 | I10: 20.41 | J10: 20.98 | K10: 22.74 | L10: 24.65 | M10: 25.1 | N10: 25.15 | O10: 24.63 | P10: 20.44 | Q10: 24.42 | R10: EIA STEO Oct-2026, table 3a
A11: OPEC other liquids | B11: mb/d | C11: 4.63 | D11: 4.65 | E11: 4.71 | F11: 4.82 | G11: 4.37 | H11: 3.06 | I11: 3.17 | J11: 3.4 | K11: 4.13 | L11: 4.84 | M11: 4.99 | N11: 5.06 | O11: 4.7 | P11: 3.5 | Q11: 4.76 | R11: EIA STEO Oct-2026, table 3a
A12: Non-OPEC total | B12: mb/d | C12: 74.91 | D12: 76.08 | E12: 78.37 | F12: 78.41 | G12: 76.2 | H12: 76.14 | I12: 77.67 | J12: 78.59 | K12: 79.24 | L12: 80.06 | M12: 80.82 | N12: 81.34 | O12: 76.96 | P12: 77.16 | Q12: 80.37 | R12: EIA STEO Oct-2026, table 3a
A13: Non-OPEC crude | B13: mb/d | C13: 53.2 | D13: 53.57 | E13: 55.18 | F13: 55.5 | G13: 54.24 | H13: 54.28 | I13: 55.28 | J13: 56.04 | K13: 56.86 | L13: 56.65 | M13: 57.09 | N13: 57.71 | O13: 54.37 | P13: 54.97 | Q13: 57.08 | R13: EIA STEO Oct-2026, table 3a
A14: Non-OPEC other liquids | B14: mb/d | C14: 21.71 | D14: 22.51 | E14: 23.19 | F14: 22.92 | G14: 21.96 | H14: 21.86 | I14: 22.39 | J14: 22.55 | K14: 22.38 | L14: 23.41 | M14: 23.73 | N14: 23.63 | O14: 22.59 | P14: 22.19 | Q14: 23.29 | R14: EIA STEO Oct-2026, table 3a
A15: CONSUMPTION
A16: World consumption | B16: mb/d | C16: 102.66 | D16: 104.45 | E16: 105.37 | F16: 105.1 | G16: 102.87 | H16: 100.04 | I16: 103.12 | J16: 103.66 | K16: 103.08 | L16: 104.6 | M16: 105.54 | N16: 105.33 | O16: 104.4 | P16: 102.43 | Q16: 104.64 | R16: EIA STEO Oct-2026, table 3a
A17: OECD total | B17: mb/d | C17: 45.66 | D17: 46.17 | E17: 46.95 | F17: 46.51 | G17: 45.91 | H17: 44.57 | I17: 46.18 | J17: 46.05 | K17: 45.72 | L17: 45.79 | M17: 46.74 | N17: 46.41 | O17: 46.33 | P17: 45.68 | Q17: 46.17 | R17: EIA STEO Oct-2026, table 3a
A18: United States | B18: mb/d | C18: 20.38 | D18: 20.68 | E18: 21.09 | F18: 20.78 | G18: 20.71 | H18: 20.53 | I18: 20.61 | J18: 20.54 | K18: 20.41 | L18: 20.78 | M18: 21.13 | N18: 20.92 | O18: 20.74 | P18: 20.6 | Q18: 20.81 | R18: EIA STEO Oct-2026, table 3a
A19: OECD Europe | B19: mb/d | C19: 13 | D19: 13.77 | E19: 13.8 | F19: 13.47 | G19: 13 | H19: 13.18 | I19: 13.86 | J19: 13.42 | K19: 13.1 | L19: 13.48 | M19: 13.89 | N19: 13.45 | O19: 13.51 | P19: 13.37 | Q19: 13.48 | R19: EIA STEO Oct-2026, table 3a
A20: Japan | B20: mb/d | C20: 3.36 | D20: 2.9 | E20: 2.9 | F20: 3.22 | G20: 3.29 | H20: 2.59 | I20: 2.8 | J20: 3.14 | K20: 3.29 | L20: 2.7 | M20: 2.75 | N20: 3.05 | O20: 3.09 | P20: 2.95 | Q20: 2.95 | R20: EIA STEO Oct-2026, table 3a
A21: Canada | B21: mb/d | C21: 2.51 | D21: 2.41 | E21: 2.66 | F21: 2.64 | G21: 2.57 | H21: 2.44 | I21: 2.61 | J21: 2.57 | K21: 2.48 | L21: 2.46 | M21: 2.6 | N21: 2.55 | O21: 2.55 | P21: 2.55 | Q21: 2.52 | R21: EIA STEO Oct-2026, table 3a
A22: U.S. Territories | B22: mb/d | C22: 0.14 | D22: 0.13 | E22: 0.15 | F22: 0.14 | G22: 0.11 | H22: 0.11 | I22: 0.12 | J22: 0.12 | K22: 0.13 | L22: 0.13 | M22: 0.14 | N22: 0.14 | O22: 0.14 | P22: 0.12 | Q22: 0.14 | R22: EIA STEO Oct-2026, table 3a
A23: Other OECD | B23: mb/d | C23: 6.27 | D23: 6.27 | E23: 6.35 | F23: 6.25 | G23: 6.23 | H23: 5.72 | I23: 6.17 | J23: 6.27 | K23: 6.3 | L23: 6.23 | M23: 6.23 | N23: 6.3 | O23: 6.29 | P23: 6.1 | Q23: 6.26 | R23: EIA STEO Oct-2026, table 3a
A24: Non-OECD total | B24: mb/d | C24: 57 | D24: 58.28 | E24: 58.42 | F24: 58.6 | G24: 56.96 | H24: 55.47 | I24: 56.94 | J24: 57.61 | K24: 57.36 | L24: 58.81 | M24: 58.8 | N24: 58.92 | O24: 58.08 | P24: 56.75 | Q24: 58.48 | R24: EIA STEO Oct-2026, table 3a
A25: China | B25: mb/d | C25: 16.41 | D25: 16.67 | E25: 16.43 | F25: 16.8 | G25: 16.56 | H25: 15.81 | I25: 15.67 | J25: 16.06 | K25: 16.13 | L25: 16.41 | M25: 16.16 | N25: 16.47 | O25: 16.58 | P25: 16.02 | Q25: 16.29 | R25: EIA STEO Oct-2026, table 3a
A26: Other Asia (incl. India) | B26: mb/d | C26: 15 | D26: 15.01 | E26: 14.58 | F26: 15.2 | G26: 15.09 | H26: 14.27 | I26: 14.54 | J26: 15.24 | K26: 15.54 | L26: 15.71 | M26: 15.26 | N26: 15.73 | O26: 14.95 | P26: 14.79 | Q26: 15.56 | R26: EIA STEO Oct-2026, table 3a
A27: Eurasia | B27: mb/d | C27: 4.86 | D27: 5.02 | E27: 5.34 | F27: 5.22 | G27: 4.86 | H27: 4.91 | I27: 5.3 | J27: 5.23 | K27: 4.78 | L27: 4.94 | M27: 5.26 | N27: 5.15 | O27: 5.11 | P27: 5.08 | Q27: 5.03 | R27: EIA STEO Oct-2026, table 3a
... A29: Other non-OECD | B29: mb/d | C29: 19.97 | D29: 20.78 | E29: 21.26 | F29: 20.56 | G29: 19.68 | H29: 19.69 | I29: 20.62 | J29: 20.26 | K29: 20.15 | L29: 20.95 | M29: 21.3 | N29: 20.75 | O29: 20.64 | P29: 20.07 | Q29: 20.79 | R29: EIA STEO Oct-2026, table 3a
A30: NET INVENTORY WITHDRAWALS (positive = stock draw)
A31: World net withdrawals | B31: mb/d | C31: -0.92 | D31: -0.74 | E31: -2.53 | F31: -3.32 | G31: -0.79 | H31: 3.55 | I31: 1.87 | J31: 0.69 | K31: -3.03 | L31: -4.95 | M31: -5.38 | N31: -6.23 | O31: -1.89 | P31: 1.34 | Q31: -4.91 | R31: EIA STEO Oct-2026, table 3a
A32: United States | B32: mb/d | C32: 0.29 | D32: -0.5 | E32: -0.52 | F32: -0.05 | G32: 0.08 | H32: 1.74 | I32: 0.05 | J32: 0.47 | K32: -0.2 | L32: -0.54 | M32: -0.85 | N32: -0.6 | O32: -0.2 | P32: 0.58 | Q32: -0.55 | R32: EIA STEO Oct-2026, table 3a
A33: Other OECD | B33: mb/d | C33: -0.3 | D33: 0.02 | E33: -0.38 | F33: 0.27 | G33: 0.28 | H33: 0.02 | I33: 0.89 | J33: 0.39 | K33: -0.53 | L33: -0.99 | M33: -1.05 | N33: -1.38 | O33: -0.1 | P33: 0.4 | Q33: -0.99 | R33: EIA STEO Oct-2026, table 3a
A34: Other inventories and balancing item | B34: mb/d | C34: -0.92 | D34: -0.26 | E34: -1.63 | F34: -3.53 | G34: -1.14 | H34: 1.79 | I34: 0.94 | J34: -0.17 | K34: -2.3 | L34: -3.42 | M34: -3.48 | N34: -4.26 | O34: -1.59 | P34: 0.36 | Q34: -3.37 | R34: EIA STEO Oct-2026, table 3a
A35: END-OF-PERIOD COMMERCIAL INVENTORIES
A36: OECD commercial inventories | B36: mb | C36: 2741 | D36: 2779 | E36: 2858 | F36: 2832 | G36: 2798 | H36: 2730 | I36: 2683 | J36: 2645 | K36: 2710 | L36: 2849 | M36: 2972 | N36: 3102 | O36: 2832 | P36: 2645 | Q36: 3102 | R36: EIA STEO Oct-2026, table 3a
A37: United States | B37: mb | C37: 1207 | D37: 1246 | E37: 1290 | F37: 1289 | G37: 1281 | H37: 1215 | I37: 1249 | J37: 1247 | K37: 1265 | L37: 1314 | M37: 1341 | N37: 1344 | O37: 1289 | P37: 1247 | Q37: 1344 | R37: EIA STEO Oct-2026, table 3a
A38: Other OECD | B38: mb | C38: 1535 | D38: 1533 | E38: 1568 | F38: 1543 | G38: 1518 | H38: 1516 | I38: 1434 | J38: 1398 | K38: 1446 | L38: 1535 | M38: 1632 | N38: 1758 | O38: 1543 | P38: 1398 | Q38: 1758 | R38: EIA STEO Oct-2026, table 3a
A39: PRICES (table 2)
A40: Brent spot | B40: $/bbl | C40: 75.83 | D40: 68.01 | E40: 69 | F40: 63.63 | G40: 81.11 | H40: 102.93 | I40: 95.95 | J40: 104.69 | K40: 94.9 | L40: 87 | M40: 80.03 | N40: 73.94 | O40: 69.04 | P40: 96.32 | Q40: 83.74 | R40: EIA STEO Oct-2026, table 2
A41: WTI spot | B41: $/bbl | C41: 71.85 | D41: 64.63 | E41: 65.78 | F41: 59.64 | G41: 72.74 | H41: 95.48 | I41: 87.02 | J41: 97 | K41: 90.9 | L41: 83 | M41: 76.03 | N41: 69.94 | O41: 65.4 | P41: 88.21 | Q41: 79.74 | R41: EIA STEO Oct-2026, table 2
A43: Consistency checks (should be ~0)
...

Sheet Agency_Check
A1: Agency comparison – annual figures
A2: mb/d · agencies use different scopes and baselines: direction matters, not the decimal
A4: Metric | B4: EIA Oct-26 | C4: IEA Oct-26 | D4: Difference | E4: OPEC Jul-26 | F4: Note
A5: Demand 2026 | B5: =EIA_Data!P$16 | C5: 102.4 | D5: =B5-C5 | E5: 105.94 | F5: OPEC uses a higher historical baseline; July figure
A6: Demand 2027 | B6: =EIA_Data!Q$16 | C6: 104.4 | D6: =B6-C6 | E6: 107.86 | F6: IEA: 102.4 + 2.0 recovery; OPEC July
A7: Demand change 2026 | B7: =EIA_Data!P$16-EIA_Data!O$16 | C7: -2.6 | D7: =B7-C7 | E7: 0.78 | F7: In July OPEC still saw growth
A8: Supply 2026 | B8: =EIA_Data!P$6 | C8: 100.7 | D8: =B8-C8
A9: Supply 2027 | B9: =EIA_Data!Q$6 | C9: 108.4 | D9: =B9-C9 | F9: IEA: 100.7 + 7.7
A10: Supply change 2026 | B10: =EIA_Data!P$6-EIA_Data!O$6 | C10: -5.8 | D10: =B10-C10
A11: Balance 2026 (supply − demand) | B11: =EIA_Data!P$6-EIA_Data!P$16 | C11: =C8-C5 | D11: =B11-C11 | F11: Both see a 2026 deficit
A12: Balance 2027 | B12: =EIA_Data!Q$6-EIA_Data!Q$16 | C12: =C9-C6 | D12: =B12-C12 | F12: Both see a large 2027 surplus
A14: Sources: EIA STEO Oct-2026 table 3a; IEA OMR Oct 14, 2026; OPEC MOMR July 2026 as reported by Argus (Jul 13). The October OPEC MOMR could not be retrieved.

Sheet OPEC+
A1: OPEC+ – crude production vs targets
A2: mb/d · source: IEA Oil Market Report Oct-2026, OPEC+ crude oil production table
A4: Country | B4: Aug-26 | C4: Sep-26 | D4: Chg m/m | E4: Target Sep-26 | F4: Vs target | G4: % of target | H4: Sustainable capacity | I4: Capacity − production | J4: Group
A5: Algeria | B5: 0.98 | C5: 0.98 | D5: =C5-B5 | E5: 1.01 | F5: =C5-E5 | G5: =IF(E5=0,0,C5/E5) | H5: 1 | I5: =H5-C5 | J5: OPEC-8
A6: Congo | B6: 0.26 | C6: 0.26 | D6: =C6-B6 | E6: 0.28 | F6: =C6-E6 | G6: =IF(E6=0,0,C6/E6) | H6: 0.27 | I6: =H6-C6 | J6: OPEC-8
A7: Equatorial Guinea | B7: 0.04 | C7: 0.04 | D7: =C7-B7 | E7: 0.07 | F7: =C7-E7 | G7: =IF(E7=0,0,C7/E7) | H7: 0.05 | I7: =H7-C7 | J7: OPEC-8
A8: Gabon | B8: 0.2 | C8: 0.19 | D8: =C8-B8 | E8: 0.18 | F8: =C8-E8 | G8: =IF(E8=0,0,C8/E8) | H8: 0.22 | I8: =H8-C8 | J8: OPEC-8
A9: Iraq | B9: 3.58 | C9: 4.1 | D9: =C9-B9 | E9: 4.43 | F9: =C9-E9 | G9: =IF(E9=0,0,C9/E9) | H9: 4.87 | I9: =H9-C9 | J9: OPEC-8
A10: Kuwait | B10: 2.04 | C10: 1.49 | D10: =C10-B10 | E10: 2.68 | F10: =C10-E10 | G10: =IF(E10=0,0,C10/E10) | H10: 2.88 | I10: =H10-C10 | J10: OPEC-8
A11: Nigeria | B11: 1.5 | C11: 1.42 | D11: =C11-B11 | E11: 1.5 | F11: =C11-E11 | G11: =IF(E11=0,0,C11/E11) | H11: 1.45 | I11: =H11-C11 | J11: OPEC-8
A12: Saudi Arabia | B12: 5.97 | C12: 8.3 | D12: =C12-B12 | E12: 10.48 | F12: =C12-E12 | G12: =IF(E12=0,0,C12/E12) | H12: 12.11 | I12: =H12-C12 | J12: OPEC-8
A13: Iran | B13: 2.16 | C13: 1.94 | D13: =C13-B13 | E13: exempt | H13: 3.8 | I13: =H13-C13 | J13: OPEC exempt
A14: Libya | B14: 1.38 | C14: 1.29 | D14: =C14-B14 | E14: exempt | H14: 1.34 | I14: =H14-C14 | J14: OPEC exempt
A15: Venezuela | B15: 1.16 | C15: 1.16 | D15: =C15-B15 | E15: exempt | H15: 1.12 | I15: =H15-C15 | J15: OPEC exempt
A16: Azerbaijan | B16: 0.41 | C16: 0.44 | D16: =C16-B16 | E16: 0.55 | F16: =C16-E16 | G16: =IF(E16=0,0,C16/E16) | H16: 0.44 | I16: =H16-C16 | J16: Non-OPEC
A17: Kazakhstan | B17: 1.87 | C17: 1.86 | D17: =C17-B17 | E17: 1.63 | F17: =C17-E17 | G17: =IF(E17=0,0,C17/E17) | H17: 1.83 | I17: =H17-C17 | J17: Non-OPEC
A18: Mexico | B18: 1.38 | C18: 1.39 | D18: =C18-B18 | E18: exempt | H18: 1.5 | I18: =H18-C18 | J18: Non-OPEC
A19: Oman | B19: 0.87 | C19: 0.89 | D19: =C19-B19 | E19: 0.84 | F19: =C19-E19 | G19: =IF(E19=0,0,C19/E19) | H19: 0.9 | I19: =H19-C19 | J19: Non-OPEC
A20: Russia | B20: 8.36 | C20: 8.43 | D20: =C20-B20 | E20: 9.95 | F20: =C20-E20 | G20: =IF(E20=0,0,C20/E20) | H20: 9.3 | I20: =H20-C20 | J20: Non-OPEC
A21: Others (Bahrain, Brunei, Malaysia, Sudan, South Sudan) | B21: 0.64 | C21: 0.64 | D21: =C21-B21 | E21: 0.87 | F21: =C21-E21 | G21: =IF(E21=0,0,C21/E21) | H21: 0.86 | I21: =H21-C21 | J21: Non-OPEC
A23: Total OPEC-8 | B23: =SUMIFS(B$5:B$21,$J$5:$J$21,"OPEC-8") | C23: =SUMIFS(C$5:C$21,$J$5:$J$21,"OPEC-8") | D23: =C23-B23 | E23: =SUMIFS(E$5:E$21,$J$5:$J$21,"OPEC-8") | F23: =SUMIFS(F$5:F$21,$J$5:$J$21,"OPEC-8") | H23: =SUMIFS(H$5:H$21,$J$5:$J$21,"OPEC-8") | I23: =H23-C23
A24: Total OPEC exempt | B24: =SUMIFS(B$5:B$21,$J$5:$J$21,"OPEC exempt") | C24: =SUMIFS(C$5:C$21,$J$5:$J$21,"OPEC exempt") | D24: =C24-B24 | H24: =SUMIFS(H$5:H$21,$J$5:$J$21,"OPEC exempt") | I24: =H24-C24
A25: Total non-OPEC (participants) | B25: =SUMIFS(B$5:B$21,$J$5:$J$21,"Non-OPEC") | C25: =SUMIFS(C$5:C$21,$J$5:$J$21,"Non-OPEC") | D25: =C25-B25 | E25: =SUMIFS(E$5:E$21,$J$5:$J$21,"Non-OPEC") | F25: =SUMIFS(F$5:F$21,$J$5:$J$21,"Non-OPEC") | H25: =SUMIFS(H$5:H$21,$J$5:$J$21,"Non-OPEC") | I25: =H25-C25
A26: Total OPEC+ | B26: =SUM(B23:B25) | C26: =SUM(C23:C25) | D26: =C26-B26 | H26: =SUM(H23:H25) | I26: =H26-C26
A28: Check vs IEA: OPEC-8 Sep 16.77 · total OPEC+ Sep 34.8 · Aug 32.8 (differences are rounding)
A29: Note: 'Capacity − production' is NOT usable spare capacity: in the Gulf most of it is blocked by the war (IEA puts effective spare at ~0.27 mb/d).
A30: 'Vs target' in the totals only counts countries that have a target.

Sheet Gulf_Flows
A1: Gulf and Hormuz – export flows
A2: mb/d · IEA OMR Oct-2026 unless stated
A4: Flow | B4: Sep-26 | C4: Chg m/m | D4: Aug-26 (calc.) | E4: Pre-war | F4: Sep vs pre-war | G4: Source
A5: Gulf producers' crude exports | B5: 13.9 | C5: 4.4 | D5: =B5-C5 | G5: IEA: >75% of pre-war
A6: Total flows through Hormuz | B6: 10.9 | C6: 3.7 | D6: =B6-C6 | G6: IEA
A7: Exports bypassing Hormuz (East-West pipeline etc.) | B7: 5.6 | C7: 0.97 | D7: =B7-C7 | G7: IEA
A8: Refined products from the Middle East | B8: 1.9 | C8: 0.21 | D8: =B8-C8 | E8: 4.7 | F8: =IF(E8=0,0,B8/E8) | G8: IEA
A9: LPG from the Middle East | B9: 0.67 | C9: 0.09 | D9: =B9-C9 | E9: 1.5 | F9: =IF(E9=0,0,B9/E9) | G9: IEA
A10: Middle East crude exports (Kpler, different scope) | B10: 16.328 | E10: 19.513 | F10: =IF(E10=0,0,B10/E10) | G10: Kpler via Al Jazeera, Feb-26 = pre-war
A12: Diesel/gasoil: global availability vs a year earlier
A13: 2Q26 | B13: -1.5 | G13: IEA: −1.5 mb/d y/y
A14: 3Q26 | B14: -1.7 | G14: IEA: −1.7 mb/d y/y
A15: Middle East + Russia net gasoil exports (Sep-26) | B15: 0.82 | C15: -1.3 | D15: =B15-C15 | G15: IEA: −1.3 mb/d y/y (column C = y/y change, D = year earlier)
A17: Read: Gulf crude is nearly back, refined products are not. That is why diesel stays expensive even with more crude on the market.

Sheet US_Weekly
A1: United States – weekly inventories and Hurricane Isaias
A2: Changes in million barrels · EIA Weekly Petroleum Status Report
A4: Week ending | B4: EIA actual | C4: Expected | D4: Surprise | E4: Read | F4: Source
A5: 2026-09-18 | B5: 2.969 | C5: -0.6 | D5: =IF(B5="","",B5-C5) | E5: =IF(B5="","pending",IF(B5-C5<0,"Draw vs consensus → bullish","Build vs consensus → bearish")) | F5: Trading Economics
A6: 2026-09-25 | B6: 0.922 | C6: -0.3 | D6: =IF(B6="","",B6-C6) | E6: =IF(B6="","pending",IF(B6-C6<0,"Draw vs consensus → bullish","Build vs consensus → bearish")) | F6: Trading Economics
A7: 2026-10-02 | B7: -3.186 | C7: 1.7 | D7: =IF(B7="","",B7-C7) | E7: =IF(B7="","pending",IF(B7-C7<0,"Draw vs consensus → bullish","Build vs consensus → bearish")) | F7: Trading Economics / EIA
A8: 2026-10-09 | C8: 1.9 | D8: =IF(B8="","",B8-C8) | E8: =IF(B8="","pending",IF(B8-C8<0,"Draw vs consensus → bullish","Build vs consensus → bearish")) | F8: Out Oct 15 18:00 CET · expected = API consensus (Investing.com)
A10: Levels and detail (week to Oct 2)
A11: Line item | B11: Value | C11: Unit | E11: Note | F11: Source
A12: Commercial crude stocks | B12: 424.1 | C12: mb | E12: ~1% above 5-year average | F12: EIA WPSR
A13: Strategic Petroleum Reserve (SPR) | B13: 283 | C13: mb | E13: Lowest since 1982 | F13: EIA WPSR
A14: Cushing stock change | B14: 0.444 | C14: mb | E14: WTI delivery hub | F14: Trading Economics
A15: Gasoline stock change | B15: 0.382 | C15: mb | F15: Trading Economics
A16: Distillate stock change | B16: -0.042 | C16: mb | E16: Distillates at lowest for early October since the 1980s (CNN) | F16: Trading Economics
A18: Hurricane Isaias – Gulf of Mexico shut-ins
A19: Gulf of Mexico offshore output (base) | B19: 2 | C19: mb/d | E19: EIA: ~2 mb/d, about 15% of U.S. crude
A20: Day | B20: % shut in | C20: mb/d shut in | E20: Note | F20: Source
A21: 2026-10-06 | B21: 0.0924 | C21: =B21*$B$19 | E21: Before evacuations | F21: MMA via Reuters/gCaptain
A22: 2026-10-07 | B22: 0.25 | C22: =B22*$B$19 | F22: MMA via Reuters/gCaptain
A23: 2026-10-08 | B23: 0.63 | C23: =B23*$B$19 | E23: 1.28 mb/d reported | F23: MMA via Reuters/gCaptain
A24: 2026-10-09 | B24: 0.72 | C24: =B24*$B$19 | E24: ~1.5 mb/d · landfall near Destin (FL) in the evening | F24: MMA via Reuters/gCaptain
A25: Production lost in the report week (mb) | C25: =SUM(C21:C24) | E25: Daily sum: barrels that never reached storage → pushes toward a draw in the Oct 15 report
A26: Market expectation (consensus) | C26: =C8
A27: Consensus minus lost production (indicative) | C27: =C26-C25 | E27: Indicative only: storm-blocked exports and imports may offset
A28: Estimated total loss from the event (mb) | C28: 7.2 | F28: Earth Science Associates

Sheet Catalysts
A1: Catalysts – calendar and risks
A2: Expected effect on the oil price
A4: When | B4: Event | C4: What to watch | D4: Expected effect | E4: Within 3 days of Oct 14 | F4: Outcome (fill in)
A5: Oct 14, 21:30–22:30 CET | B5: API inventories (week to Oct 9) | C5: Consensus +1.9 mb: a build would be bearish | D5: Uncertain | E5: Yes
A6: Oct 15, 18:00 CET | B6: EIA inventories (week to Oct 9) | C6: Draw risk from the Gulf of Mexico shut-ins | D6: Up | E6: Yes
A7: Ongoing | B7: Houthi attacks on Saudi Arabia | C7: Saudi response promised: gap risk | D7: Up | E7: Yes
A8: Ongoing | B8: Tanker attacks in Hormuz | C8: At a 7-month high | D8: Up | E8: Yes
A9: Ongoing | B9: Gulf of Mexico production restart | C9: Platforms restarting after Isaias | D9: Down | E9: Yes
A10: Ongoing | B10: US–Iran talks via Qatar | C10: A deal would deflate the geopolitical premium (~$20) | D10: Down | E10: Yes
A11: Ongoing | B11: Russia–Ukraine energy truce | C11: Fragile; Russian diesel volumes are small | D11: Down | E11: Yes
A12: Oct 17–18 | B12: Weekend | C12: News over the weekend: Monday gap risk | D12: Uncertain | E12: Yes
A13: Oct 21, 16:30 CET | B13: EIA – first full week after the hurricane | C13: Production recovery | D13: Uncertain | E13: No
A14: Nov 1 | B14: OPEC+ meeting | C14: No change expected before 2027 | D14: Neutral | E14: No
A15: Nov 10 | B15: EIA Short-Term Energy Outlook | C15: New price and inventory forecasts | D15: Uncertain | E15: No
A16: Nov 13 | B16: IEA Oil Market Report | C16: Updated global balance: refresh EIA_Data / Agency_Check | D16: Uncertain | E16: No
