Workbook

Sheet README
A1: GLOBAL SOYBEAN SUPPLY & DEMAND MODEL - 2026/27
A2: Global soybean supply & demand model | As of 13-Oct-2026 (post 9-Oct WASDE) | Units: US in million bushels, world in million metric tons
A4: HEADLINE (live from model)
A5: US ending stocks 2026/27 - USDA Oct (M bu) | B5: =US_BS!F17
A6: US ending stocks 2026/27 - HOUSE (M bu) | B6: =US_BS!G17
A7: US stocks/use - USDA vs HOUSE | B7: =US_BS!F18
B8: =US_BS!G18
A9: World ending stocks - USDA vs HOUSE (MMT) | B9: =World_BS!I23
B10: =World_BS!I34
A11: Implied SAFP change House vs USDA ($/bu) | B11: =Price_Model!C29
A12: Board crush margin ($/bu) | B12: =Crush!B12
A13: Nov/Jan carry as % of full carry | B13: =Spreads!I5
A15: HOUSE VIEW
A16: Market prices US 2026/27 off USDA's 315 mb carryout; we see ~200-210 mb (S/U ~4.5%).
A17: Drivers: (1) board crush margin >$2/bu keeps plants at capacity -> crush +40 mb; (2) China buying ahead of USDA pace -> exports +50 mb;
A18: (3) yield 52.9 bpa (trend 53.5 less condition adj.) vs USDA 53.1. Supply story is priced; demand is under-priced.
A19: Market signal to watch: the Nov/Jan spread vs full carry (narrowing carry = nearby tightness) - see Spreads tab.
A20: Risks: yield >54 bpa (StoneX), China tariff persists / CASDE 95.5 MMT imports, meal glut compressing crush margins, record Brazil crop from Jan.
A22: TABS
A23: Inputs | B23: All house-view levers, market prices, conventions. Edit here only.
A24: US_BS | B24: US balance sheet: 2024/25, 2025/26, 2026/27 USDA Sep/Oct, HOUSE, delta, reconciliation checks.
A25: World_BS | B25: World & country balances (US, Brazil, Argentina, Paraguay, China, RoW): USDA 25/26, 26/27 and HOUSE; key metrics; checks.
A26: Price_Model | B26: SAFP vs ln(stocks/use) regression (SUMPRODUCT OLS with include flags) -> implied price for House vs USDA.
A27: Scenarios | B27: Yield x exports grids -> US ending stocks, S/U, implied price.
A28: Crush | B28: Board crush margin + oil/meal sensitivity.
A29: Spreads | B29: Nov/Jan & Jan/Mar spreads vs full carry: % of full carry as a read on nearby tightness.
A30: Sources | B30: Every source with link and vintage; release calendar for updates.
A32: COLOUR CODE
A33: Blue text = hard-coded input (sourced)
A34: Yellow fill = key house-view lever
A35: Black = formula
A36: Green = link to another sheet
A37: Light-green fill = key output
A39: CAVEATS
A40: Historical total use & SAFP (2014/15-2023/24) are approximations - verify vs USDA PSD before relying on the price regression [S13].
A41: FAS country tables omit some items (Brazil/Paraguay imports, Paraguay stocks, China exports): set to 0 and absorbed in Rest of World.
A42: Market prices on Inputs are as of 6-Oct-26 / estimates - refresh from CQG before using Crush or Spreads tabs.
A43: Price regression R2 is low: stocks/use explains only part of price (China policy, biofuels, FX). Use deltas, not levels.

Sheet Inputs
A1: INPUTS & HOUSE-VIEW LEVERS
A2: Edit yellow/blue cells only. Every model sheet reads from here. As of 13-Oct-2026 (post Oct-9 WASDE).
A4: Parameter | B4: Value | C4: Unit | D4: USDA Oct-26 | E4: Source / rationale
A5: CONVERSIONS
A6: Bushels per metric ton (soybeans) | B6: 36.7437 | C6: bu/MT | E6: Standard conversion (60 lb/bu). [S9]
A7: US 2026/27 - HOUSE VIEW
A8: Area harvested | B8: 85.9 | C8: M acres | D8: 85.9 | E8: Unchanged vs USDA. [S1]
A9: Yield | B9: 52.9 | C9: bu/acre | D9: 53.1 | E9: House yield model (trend 53.5 - condition adj -0.6). See soy_yield_model.py. [S1][S6]
A10: Imports | B10: 25 | C10: M bu | D10: 25 | E10: USDA. [S1]
A11: Crush | B11: 2820 | C11: M bu | D11: 2780 | E11: Board crush margin ~$2.45/bu (see Crush tab) -> plants at capacity; +40 mb vs USDA. [S1][S5]
A12: Exports | B12: 1745 | C12: M bu | D12: 1695 | E12: China buying ahead of USDA pace: commitments +89% y/y, 10.8 MMT unshipped to China. +50 mb vs USDA. [S1][S7]
A13: Seed | B13: 73 | C13: M bu | D13: 73 | E13: USDA. [S1]
A14: Residual | B14: 39 | C14: M bu | D14: 39 | E14: USDA. [S1]
A15: SOUTH AMERICA / CHINA - HOUSE VIEW
A16: Brazil production 2026/27 | B16: 186 | C16: MMT | D16: 186 | E16: Held at USDA; CONAB first est. 181.6 - downside risk to USDA. [S2][S8]
A17: Brazil: share of prod. change exported | B17: 0.8 | C17: ratio | E17: Assumption: ~80% of marginal Brazil crop goes to export (crush capacity-bound).
A18: Brazil exports displaced per t extra US exports | B18: 0.5 | C18: ratio | E18: Assumption: half of extra US sales to China displace Brazilian origin.
A19: Argentina production 2026/27 | B19: 50 | C19: MMT | D19: 50 | E19: Held at USDA. [S2]
A20: China imports 2026/27 | B20: 115 | C20: MMT | D20: 115 | E20: Held at USDA; CASDE (May) 95.5 MMT - key disagreement. [S2][S10]
A21: China: crush pass-through of import change | B21: 1 | C21: ratio | E21: Assumption: incremental imports crushed 1:1.
A22: MARKET (update from CQG)
A23: Soybeans Nov-26 (ZSX26) | B23: 1303 | C23: c/bu | E23: 6-Oct-26 settle (Brownfield). UPDATE. [S4]
A24: Soybeans Jan-27 (ZSF27) | B24: 1320 | C24: c/bu | E24: Estimate (Nov + ~17c). UPDATE from CQG.
A25: Soybeans Mar-27 (ZSH27) | B25: 1330 | C25: c/bu | E25: Estimate (Nov + ~27c on 5-Oct). UPDATE from CQG.
A26: Soybean meal Dec-26 (ZMZ26) | B26: 354.8 | C26: $/short ton | E26: 6-Oct-26 settle. [S4]
A27: Soybean oil Dec-26 (ZLZ26) | B27: 69.91 | C27: c/lb | E27: 6-Oct-26 settle. [S4]
A28: CBOT soybean storage rate | B28: 0.165 | C28: c/bu/day | E28: VERIFY vs current CBOT shipping-certificate storage rate.
A29: Financing rate | B29: 0.05 | C29: % p.a. | E29: Assumption: SOFR ~3.9% + ~110bp funding spread. [S11]
A30: Days Nov-26 -> Jan-27 | B30: 61 | C30: days | E30: Mid-month to mid-month.
A31: Days Jan-27 -> Mar-27 | B31: 59 | C31: days | E31: Mid-month to mid-month.
A32: CRUSH CONVENTIONS
A33: Meal yield | B33: 44 | C33: lb/bu | E33: Board crush convention (48% protein meal).
A34: Oil yield | B34: 11 | C34: lb/bu | E34: Board crush convention.

Sheet US_BS
A1: US SOYBEAN BALANCE SHEET (million bushels unless stated)
A2: Marketing year Sep-Aug. History & USDA columns = USDA WASDE (blue). House column = Inputs levers (green links). Totals = formulas.
A4: Item | B4: Unit | C4: 2024/25 | D4: 2025/26 Est | E4: 2026/27 USDA Sep | F4: 2026/27 USDA Oct | G4: 2026/27 HOUSE | H4: House - USDA Oct | I4: Source
A5: Area planted | B5: M acres | C5: 87.3 | D5: 81.2 | E5: 86.9 | F5: 86.9 | G5: =F5 | H5: =G5-F5 | I5: [S1] WASDE Oct-26
A6: Area harvested | B6: M acres | C6: 86.2 | D6: 80.4 | E6: 85.9 | F6: 85.9 | G6: =Inputs!$B$8 | H6: =G6-F6
A7: Yield | B7: bu/acre | C7: 50.7 | D7: 53 | E7: 52.8 | F7: 53.1 | G7: =Inputs!$B$9 | H7: =G7-F7 | I7: House = Inputs (yield model)
A8: Beginning stocks | B8: M bu | C8: 342 | D8: =C17 | E8: 325 | F8: =D17 | G8: =F8 | H8: =G8-F8 | I8: [S1]; Sep-1 stocks 315 [S3]
A9: Production | B9: M bu | C9: 4374 | D9: 4261 | E9: =E6*E7 | F9: =F6*F7 | G9: =G6*G7 | H9: =G9-F9
A10: Imports | B10: M bu | C10: 30 | D10: 22 | E10: 25 | F10: 25 | G10: =Inputs!$B$10 | H10: =G10-F10
A11: TOTAL SUPPLY | B11: M bu | C11: =SUM(C8:C10) | D11: =SUM(D8:D10) | E11: =SUM(E8:E10) | F11: =SUM(F8:F10) | G11: =SUM(G8:G10) | H11: =G11-F11
A12: Crush | B12: M bu | C12: 2445 | D12: 2646 | E12: 2780 | F12: 2780 | G12: =Inputs!$B$11 | H12: =G12-F12 | I12: [S1]; House: margin-driven (Crush tab)
A13: Exports | B13: M bu | C13: 1892 | D13: 1515 | E13: 1685 | F13: 1695 | G13: =Inputs!$B$12 | H13: =G13-F13 | I13: [S1]; House: China pace (Export Sales [S7])
A14: Seed | B14: M bu | C14: 70 | D14: 75 | E14: 73 | F14: 73 | G14: =Inputs!$B$13 | H14: =G14-F14
A15: Residual | B15: M bu | C15: 14 | D15: 57 | E15: 38 | F15: 39 | G15: =Inputs!$B$14 | H15: =G15-F15
A16: TOTAL USE | B16: M bu | C16: =SUM(C12:C15) | D16: =SUM(D12:D15) | E16: =SUM(E12:E15) | F16: =SUM(F12:F15) | G16: =SUM(G12:G15) | H16: =G16-F16
A17: ENDING STOCKS | B17: M bu | C17: =C11-C16 | D17: =D11-D16 | E17: =E11-E16 | F17: =F11-F16 | G17: =G11-G16 | H17: =G17-F17
A18: Stocks / use | B18: % | C18: =IF(C16=0,0,C17/C16) | D18: =IF(D16=0,0,D17/D16) | E18: =IF(E16=0,0,E17/E16) | F18: =IF(F16=0,0,F17/F16) | G18: =IF(G16=0,0,G17/G16) | H18: =G18-F18
A19: Avg farm price (USDA) | B19: $/bu | C19: 10 | D19: 10.5 | E19: 12 | F19: 12 | G19: =Price_Model!$C$27 | I19: House col = price implied by Price_Model (S/U regression)
A20: Memo (MMT): Production | B20: MMT | C20: =C9/Inputs!$B$6 | D20: =D9/Inputs!$B$6 | E20: =E9/Inputs!$B$6 | F20: =F9/Inputs!$B$6 | G20: =G9/Inputs!$B$6 | H20: =G20-F20
A21: Memo (MMT): Crush | B21: MMT | C21: =C12/Inputs!$B$6 | D21: =D12/Inputs!$B$6 | E21: =E12/Inputs!$B$6 | F21: =F12/Inputs!$B$6 | G21: =G12/Inputs!$B$6 | H21: =G21-F21
A22: Memo (MMT): Exports | B22: MMT | C22: =C13/Inputs!$B$6 | D22: =D13/Inputs!$B$6 | E22: =E13/Inputs!$B$6 | F22: =F13/Inputs!$B$6 | G22: =G13/Inputs!$B$6 | H22: =G22-F22
A23: Memo (MMT): Ending stocks | B23: MMT | C23: =C17/Inputs!$B$6 | D23: =D17/Inputs!$B$6 | E23: =E17/Inputs!$B$6 | F23: =F17/Inputs!$B$6 | G23: =G17/Inputs!$B$6 | H23: =G23-F23
A24: Check: USDA reported ending stocks | B24: M bu | C24: 325 | D24: 315 | E24: 310 | F24: 315
A25: Check: model - reported | B25: M bu | C25: =C17-C24 | D25: =D17-D24 | E25: =E17-E24 | F25: =F17-F24 | I25: Rounding vs USDA published (should be within +/-2)

Sheet World_BS
A1: WORLD SOYBEAN BALANCE SHEET (million metric tons)
A2: USDA blocks = FAS Oilseeds: World Markets & Trade, Oct-26 [S2]. Rest of World = World minus named countries. 'Other use' = implied (seed/feed/food/residual).
A4: 2025/26 - USDA (Oct-26)
A5: Country | B5: Beg stocks | C5: Production | D5: Imports | E5: Crush | F5: Other use (impl.) | G5: Total dom. use | H5: Exports | I5: End stocks | J5: Stocks/use
A6: United States | B6: 8.84 | C6: 115.966 | D6: =US_BS!D10/Inputs!$B$6 | E6: 72.003 | F6: =B6+C6+D6-E6-H6-I6 | G6: =E6+F6 | H6: 41.243 | I6: 8.577 | J6: =IF((G6+H6)=0,0,I6/(G6+H6))
A7: Brazil | B7: 37.688 | C7: 180.5 | D7: 0 | E7: 62.5 | F7: =B7+C7+D7-E7-H7-I7 | G7: =E7+F7 | H7: 114.46 | I7: 37.881 | J7: =IF((G7+H7)=0,0,I7/(G7+H7))
A8: Argentina | B8: 24.671 | C8: 49.3 | D8: 7.5 | E8: 43 | F8: =B8+C8+D8-E8-H8-I8 | G8: =E8+F8 | H8: 8.9 | I8: 23.671 | J8: =IF((G8+H8)=0,0,I8/(G8+H8))
A9: Paraguay | B9: 0 | C9: 12.1 | D9: 0 | E9: 3.8 | F9: =B9+C9+D9-E9-H9-I9 | G9: =E9+F9 | H9: 8.2 | I9: 0 | J9: =IF((G9+H9)=0,0,I9/(G9+H9))
A10: China | B10: 44.489 | C10: 20.9 | D10: 113 | E10: 109 | F10: =B10+C10+D10-E10-H10-I10 | G10: =E10+F10 | H10: 0 | I10: 44.359 | J10: =IF((G10+H10)=0,0,I10/(G10+H10))
A11: Rest of World | B11: =B12-SUM(B6:B10) | C11: =C12-SUM(C6:C10) | D11: =D12-SUM(D6:D10) | E11: =E12-SUM(E6:E10) | F11: =B11+C11+D11-E11-H11-I11 | G11: =E11+F11 | H11: =H12-SUM(H6:H10) | I11: =I12-SUM(I6:I10) | J11: =IF((G11+H11)=0,0,I11/(G11+H11))
A12: WORLD | B12: 125.965 | C12: 429.185 | D12: 188.527 | E12: 375.838 | F12: =B12+C12+D12-E12-H12-I12 | G12: =E12+F12 | H12: 186.423 | I12: 124.927 | J12: =IF((G12+H12)=0,0,I12/(G12+H12))
A15: 2026/27 - USDA (Oct-26)
A16: Country | B16: Beg stocks | C16: Production | D16: Imports | E16: Crush | F16: Other use (impl.) | G16: Total dom. use | H16: Exports | I16: End stocks | J16: Stocks/use
A17: United States | B17: =I6 | C17: 124.147 | D17: =US_BS!F10/Inputs!$B$6 | E17: 75.659 | F17: =B17+C17+D17-E17-H17-I17 | G17: =E17+F17 | H17: 46.13 | I17: 8.572 | J17: =IF((G17+H17)=0,0,I17/(G17+H17))
A18: Brazil | B18: =I7 | C18: 186 | D18: 0 | E18: 65 | F18: =B18+C18+D18-E18-H18-I18 | G18: =E18+F18 | H18: 118 | I18: 37.281 | J18: =IF((G18+H18)=0,0,I18/(G18+H18))
A19: Argentina | B19: =I8 | C19: 50 | D19: 6.5 | E19: 43.5 | F19: =B19+C19+D19-E19-H19-I19 | G19: =E19+F19 | H19: 6.45 | I19: 24.071 | J19: =IF((G19+H19)=0,0,I19/(G19+H19))
A20: Paraguay | B20: =I9 | C20: 11.1 | D20: 0 | E20: 3.6 | F20: =B20+C20+D20-E20-H20-I20 | G20: =E20+F20 | H20: 7.35 | I20: 0 | J20: =IF((G20+H20)=0,0,I20/(G20+H20))
A21: China | B21: =I10 | C21: 21 | D21: 115 | E21: 111 | F21: =B21+C21+D21-E21-H21-I21 | G21: =E21+F21 | H21: 0 | I21: 44.259 | J21: =IF((G21+H21)=0,0,I21/(G21+H21))
A22: Rest of World | B22: =B23-SUM(B17:B21) | C22: =C23-SUM(C17:C21) | D22: =D23-SUM(D17:D21) | E22: =E23-SUM(E17:E21) | F22: =B22+C22+D22-E22-H22-I22 | G22: =E22+F22 | H22: =H23-SUM(H17:H21) | I22: =I23-SUM(I17:I21) | J22: =IF((G22+H22)=0,0,I22/(G22+H22))
A23: WORLD | B23: =I12 | C23: 442.7 | D23: 190.823 | E23: 385.714 | F23: =B23+C23+D23-E23-H23-I23 | G23: =E23+F23 | H23: 191.995 | I23: 124.278 | J23: =IF((G23+H23)=0,0,I23/(G23+H23))
A26: 2026/27 - HOUSE VIEW
A27: Country | B27: Beg stocks | C27: Production | D27: Imports | E27: Crush | F27: Other use (impl.) | G27: Total dom. use | H27: Exports | I27: End stocks | J27: Stocks/use
A28: United States | B28: =B17 | C28: =US_BS!G9/Inputs!$B$6 | D28: =US_BS!G10/Inputs!$B$6 | E28: =US_BS!G12/Inputs!$B$6 | F28: =B28+C28+D28-E28-H28-I28 | G28: =E28+F28 | H28: =US_BS!G13/Inputs!$B$6 | I28: =US_BS!G17/Inputs!$B$6 | J28: =IF((G28+H28)=0,0,I28/(G28+H28))
A29: Brazil | B29: =B18 | C29: =Inputs!$B$16 | D29: =D18 | E29: =E18 | F29: =F18 | G29: =E29+F29 | H29: =H18+(C29-C18)*Inputs!$B$17-(H28-H17)*Inputs!$B$18 | I29: =B29+C29+D29-E29-F29-H29 | J29: =IF((G29+H29)=0,0,I29/(G29+H29))
A30: Argentina | B30: =B19 | C30: =Inputs!$B$19 | D30: =D19 | E30: =E19 | F30: =F19 | G30: =E30+F30 | H30: =H19 | I30: =B30+C30+D30-E30-F30-H30 | J30: =IF((G30+H30)=0,0,I30/(G30+H30))
A31: Paraguay | B31: =B20 | C31: =C20 | D31: =D20 | E31: =E20 | F31: =F20 | G31: =E31+F31 | H31: =H20 | I31: =B31+C31+D31-E31-F31-H31 | J31: =IF((G31+H31)=0,0,I31/(G31+H31))
A32: China | B32: =B21 | C32: =C21 | D32: =Inputs!$B$20 | E32: =E21+(D32-D21)*Inputs!$B$21 | F32: =F21 | G32: =E32+F32 | H32: =H21 | I32: =B32+C32+D32-E32-F32-H32 | J32: =IF((G32+H32)=0,0,I32/(G32+H32))
A33: Rest of World | B33: =B22 | C33: =C22 | D33: =D22+((H28-H17)+(H29-H18)+(H30-H19)+(H31-H20)+(H32-H21))-((D28-D17)+(D29-D18)+(D30-D19)+(D31-D20)+(D32-D21)) | E33: =E22 | F33: =F22 | G33: =E33+F33 | H33: =H22 | I33: =B33+C33+D33-E33-F33-H33 | J33: =IF((G33+H33)=0,0,I33/(G33+H33)) | K33: RoW imports absorb any net change in world trade (exports - imports) so trade balances vs USDA.
A34: WORLD | B34: =SUM(B28:B33) | C34: =SUM(C28:C33) | D34: =SUM(D28:D33) | E34: =SUM(E28:E33) | F34: =SUM(F28:F33) | G34: =E34+F34 | H34: =SUM(H28:H33) | I34: =SUM(I28:I33) | J34: =IF((G34+H34)=0,0,I34/(G34+H34))
A37: KEY METRICS
A38: Metric | B38: 2025/26 USDA | C38: 2026/27 USDA | D38: 2026/27 HOUSE | E38: House - USDA
A39: World ending stocks (MMT) | B39: =I12 | C39: =I23 | D39: =I34 | E39: =D39-C39
A40: World stocks / use | B40: =J12 | C40: =J23 | D40: =J34 | E40: =D40-C40
A41: World ex-China ending stocks (MMT) | B41: =I12-I10 | C41: =I23-I21 | D41: =I34-I32 | E41: =D41-C41
A42: World ex-China stocks / use | B42: =(I12-I10)/((G12+H12)-(G10+H10)) | C42: =(I23-I21)/((G23+H23)-(G21+H21)) | D42: =(I34-I32)/((G34+H34)-(G32+H32)) | E42: =D42-C42
A43: Major exporters stocks: US+BR+AR (MMT) | B43: =I6+I7+I8 | C43: =I17+I18+I19 | D43: =I28+I29+I30 | E43: =D43-C43
A44: Exporter stocks / exporter use (US+BR+AR) | B44: =(I6+I7+I8)/(G6+H6+G7+H7+G8+H8) | C44: =(I17+I18+I19)/(G17+H17+G18+H18+G19+H19) | D44: =(I28+I29+I30)/(G28+H28+G29+H29+G30+H30) | E44: =D44-C44
A45: US share of world exports | B45: =H6/H12 | C45: =H17/H23 | D45: =H28/H34 | E45: =D45-C45
A46: Brazil share of world exports | B46: =H7/H12 | C46: =H18/H23 | D46: =H29/H34 | E46: =D46-C46
A47: China share of world imports | B47: =D10/D12 | C47: =D21/D23 | D47: =D32/D34 | E47: =D47-C47
...

Sheet Price_Model
A1: PRICE MODEL: US season-average farm price vs ln(stocks/use)
A2: Weighted OLS via SUMPRODUCT; set Include=0 to drop structural-break years (e.g. trade war). Low R2 = S/U is necessary but not sufficient.
A4: Marketing yr | B4: End stocks (M bu) | C4: Total use (M bu) | D4: Stocks/use | E4: ln(S/U) | F4: SAFP ($/bu) | G4: Include (1/0) | H4: Fitted ($/bu) | I4: Residual
A5: 2014/15 | B5: 190.6 | C5: 3861 | D5: =B5/C5 | E5: =LN(D5) | F5: 10.1 | G5: 1 | H5: =$C$23+$C$22*E5 | I5: =F5-H5
A6: 2015/16 | B6: 196.7 | C6: 3944 | D6: =B6/C6 | E6: =LN(D6) | F6: 8.95 | G6: 1 | H6: =$C$23+$C$22*E6 | I6: =F6-H6
A7: 2016/17 | B7: 301.6 | C7: 4213 | D7: =B7/C7 | E7: =LN(D7) | F7: 9.47 | G7: 1 | H7: =$C$23+$C$22*E7 | I7: =F7-H7
A8: 2017/18 | B8: 438.1 | C8: 4298 | D8: =B8/C8 | E8: =LN(D8) | F8: 9.33 | G8: 1 | H8: =$C$23+$C$22*E8 | I8: =F8-H8
A9: 2018/19 | B9: 925.1 | C9: 3955 | D9: =B9/C9 | E9: =LN(D9) | F9: 8.48 | G9: 1 | H9: =$C$23+$C$22*E9 | I9: =F9-H9
A10: 2019/20 | B10: 538.5 | C10: 3938 | D10: =B10/C10 | E10: =LN(D10) | F10: 8.57 | G10: 1 | H10: =$C$23+$C$22*E10 | I10: =F10-H10
A11: 2020/21 | B11: 257 | C11: 4504 | D11: =B11/C11 | E11: =LN(D11) | F11: 10.8 | G11: 1 | H11: =$C$23+$C$22*E11 | I11: =F11-H11
A12: 2021/22 | B12: 274.4 | C12: 4464 | D12: =B12/C12 | E12: =LN(D12) | F12: 13.3 | G12: 1 | H12: =$C$23+$C$22*E12 | I12: =F12-H12
A13: 2022/23 | B13: 264.2 | C13: 4305 | D13: =B13/C13 | E13: =LN(D13) | F13: 14.2 | G13: 1 | H13: =$C$23+$C$22*E13 | I13: =F13-H13
A14: 2023/24 | B14: 342.4 | C14: 4105 | D14: =B14/C14 | E14: =LN(D14) | F14: 12.4 | G14: 1 | H14: =$C$23+$C$22*E14 | I14: =F14-H14
A15: 2024/25 | B15: =US_BS!C17 | C15: =US_BS!C16 | D15: =B15/C15 | E15: =LN(D15) | F15: 10 | G15: 1 | H15: =$C$23+$C$22*E15 | I15: =F15-H15
A16: 2025/26 | B16: =US_BS!D17 | C16: =US_BS!D16 | D16: =B16/C16 | E16: =LN(D16) | F16: 10.5 | G16: 1 | H16: =$C$23+$C$22*E16 | I16: =F16-H16
A19: REGRESSION | B19: n (included) | C19: =SUM(G5:G16)
B20: Mean ln(S/U) | C20: =SUMPRODUCT(G5:G16,E5:E16)/C19
B21: Mean price | C21: =SUMPRODUCT(G5:G16,F5:F16)/C19
B22: Slope ($ per unit ln S/U) | C22: =SUMPRODUCT(G5:G16,E5:E16-C20,F5:F16-C21)/SUMPRODUCT(G5:G16,E5:E16-C20,E5:E16-C20)
B23: Intercept | C23: =C21-C22*C20
B24: R-squared | C24: =1-SUMPRODUCT(G5:G16,((F5:F16)-($C$23+$C$22*(E5:E16)))^2)/SUMPRODUCT(G5:G16,((F5:F16)-C21)^2)
A25: IMPLIED 2026/27 PRICE
B26: Case | C26: Implied SAFP ($/bu) | D26: S/U | E26: USDA SAFP
B27: HOUSE | C27: =$C$23+$C$22*LN(D27) | D27: =US_BS!G18
B28: USDA Oct | C28: =$C$23+$C$22*LN(D28) | D28: =US_BS!F18 | E28: =US_BS!F19
B29: House - USDA ($/bu) | C29: =C27-C28
A31: Read-across: SAFP is a farm-gate average; Nov futures trade ~$0.5-1.0 over SAFP in tight years (basis). Use the CHANGE (C29) as the signal, not the level.
A32: Structural breaks: 2018/19-2019/20 (US-China trade war) and 2024-26 (tariffs, biofuel policy) weaken the fit - test with Include=0.

Sheet Scenarios
A1: SCENARIO GRIDS - US 2026/27
A2: Other balance-sheet items held at House view (US_BS col G). Rows = yield, columns = exports.
A4: 1) Ending stocks (M bu)
A5: Yield \ Exports (M bu) | B5: 1600 | C5: 1650 | D5: 1695 | E5: 1745 | F5: 1800 | G5: 1850
A6: 51.5 | B6: =(US_BS!$G$8+US_BS!$G$6*$A6+US_BS!$G$10-(US_BS!$G$12+B$5+US_BS!$G$14+US_BS!$G$15)) | C6: =(US_BS!$G$8+US_BS!$G$6*$A6+US_BS!$G$10-(US_BS!$G$12+C$5+US_BS!$G$14+US_BS!$G$15)) | D6: =(US_BS!$G$8+US_BS!$G$6*$A6+US_BS!$G$10-(US_BS!$G$12+D$5+US_BS!$G$14+US_BS!$G$15)) | E6: =(US_BS!$G$8+US_BS!$G$6*$A6+US_BS!$G$10-(US_BS!$G$12+E$5+US_BS!$G$14+US_BS!$G$15)) | F6: =(US_BS!$G$8+US_BS!$G$6*$A6+US_BS!$G$10-(US_BS!$G$12+F$5+US_BS!$G$14+US_BS!$G$15)) | G6: =(US_BS!$G$8+US_BS!$G$6*$A6+US_BS!$G$10-(US_BS!$G$12+G$5+US_BS!$G$14+US_BS!$G$15))
A7: 52 | B7: =(US_BS!$G$8+US_BS!$G$6*$A7+US_BS!$G$10-(US_BS!$G$12+B$5+US_BS!$G$14+US_BS!$G$15)) | C7: =(US_BS!$G$8+US_BS!$G$6*$A7+US_BS!$G$10-(US_BS!$G$12+C$5+US_BS!$G$14+US_BS!$G$15)) | D7: =(US_BS!$G$8+US_BS!$G$6*$A7+US_BS!$G$10-(US_BS!$G$12+D$5+US_BS!$G$14+US_BS!$G$15)) | E7: =(US_BS!$G$8+US_BS!$G$6*$A7+US_BS!$G$10-(US_BS!$G$12+E$5+US_BS!$G$14+US_BS!$G$15)) | F7: =(US_BS!$G$8+US_BS!$G$6*$A7+US_BS!$G$10-(US_BS!$G$12+F$5+US_BS!$G$14+US_BS!$G$15)) | G7: =(US_BS!$G$8+US_BS!$G$6*$A7+US_BS!$G$10-(US_BS!$G$12+G$5+US_BS!$G$14+US_BS!$G$15))
A8: 52.5 | B8: =(US_BS!$G$8+US_BS!$G$6*$A8+US_BS!$G$10-(US_BS!$G$12+B$5+US_BS!$G$14+US_BS!$G$15)) | C8: =(US_BS!$G$8+US_BS!$G$6*$A8+US_BS!$G$10-(US_BS!$G$12+C$5+US_BS!$G$14+US_BS!$G$15)) | D8: =(US_BS!$G$8+US_BS!$G$6*$A8+US_BS!$G$10-(US_BS!$G$12+D$5+US_BS!$G$14+US_BS!$G$15)) | E8: =(US_BS!$G$8+US_BS!$G$6*$A8+US_BS!$G$10-(US_BS!$G$12+E$5+US_BS!$G$14+US_BS!$G$15)) | F8: =(US_BS!$G$8+US_BS!$G$6*$A8+US_BS!$G$10-(US_BS!$G$12+F$5+US_BS!$G$14+US_BS!$G$15)) | G8: =(US_BS!$G$8+US_BS!$G$6*$A8+US_BS!$G$10-(US_BS!$G$12+G$5+US_BS!$G$14+US_BS!$G$15))
A9: 52.9 | B9: =(US_BS!$G$8+US_BS!$G$6*$A9+US_BS!$G$10-(US_BS!$G$12+B$5+US_BS!$G$14+US_BS!$G$15)) | C9: =(US_BS!$G$8+US_BS!$G$6*$A9+US_BS!$G$10-(US_BS!$G$12+C$5+US_BS!$G$14+US_BS!$G$15)) | D9: =(US_BS!$G$8+US_BS!$G$6*$A9+US_BS!$G$10-(US_BS!$G$12+D$5+US_BS!$G$14+US_BS!$G$15)) | E9: =(US_BS!$G$8+US_BS!$G$6*$A9+US_BS!$G$10-(US_BS!$G$12+E$5+US_BS!$G$14+US_BS!$G$15)) | F9: =(US_BS!$G$8+US_BS!$G$6*$A9+US_BS!$G$10-(US_BS!$G$12+F$5+US_BS!$G$14+US_BS!$G$15)) | G9: =(US_BS!$G$8+US_BS!$G$6*$A9+US_BS!$G$10-(US_BS!$G$12+G$5+US_BS!$G$14+US_BS!$G$15))
A10: 53.1 | B10: =(US_BS!$G$8+US_BS!$G$6*$A10+US_BS!$G$10-(US_BS!$G$12+B$5+US_BS!$G$14+US_BS!$G$15)) | C10: =(US_BS!$G$8+US_BS!$G$6*$A10+US_BS!$G$10-(US_BS!$G$12+C$5+US_BS!$G$14+US_BS!$G$15)) | D10: =(US_BS!$G$8+US_BS!$G$6*$A10+US_BS!$G$10-(US_BS!$G$12+D$5+US_BS!$G$14+US_BS!$G$15)) | E10: =(US_BS!$G$8+US_BS!$G$6*$A10+US_BS!$G$10-(US_BS!$G$12+E$5+US_BS!$G$14+US_BS!$G$15)) | F10: =(US_BS!$G$8+US_BS!$G$6*$A10+US_BS!$G$10-(US_BS!$G$12+F$5+US_BS!$G$14+US_BS!$G$15)) | G10: =(US_BS!$G$8+US_BS!$G$6*$A10+US_BS!$G$10-(US_BS!$G$12+G$5+US_BS!$G$14+US_BS!$G$15))
A11: 53.5 | B11: =(US_BS!$G$8+US_BS!$G$6*$A11+US_BS!$G$10-(US_BS!$G$12+B$5+US_BS!$G$14+US_BS!$G$15)) | C11: =(US_BS!$G$8+US_BS!$G$6*$A11+US_BS!$G$10-(US_BS!$G$12+C$5+US_BS!$G$14+US_BS!$G$15)) | D11: =(US_BS!$G$8+US_BS!$G$6*$A11+US_BS!$G$10-(US_BS!$G$12+D$5+US_BS!$G$14+US_BS!$G$15)) | E11: =(US_BS!$G$8+US_BS!$G$6*$A11+US_BS!$G$10-(US_BS!$G$12+E$5+US_BS!$G$14+US_BS!$G$15)) | F11: =(US_BS!$G$8+US_BS!$G$6*$A11+US_BS!$G$10-(US_BS!$G$12+F$5+US_BS!$G$14+US_BS!$G$15)) | G11: =(US_BS!$G$8+US_BS!$G$6*$A11+US_BS!$G$10-(US_BS!$G$12+G$5+US_BS!$G$14+US_BS!$G$15))
A12: 54 | B12: =(US_BS!$G$8+US_BS!$G$6*$A12+US_BS!$G$10-(US_BS!$G$12+B$5+US_BS!$G$14+US_BS!$G$15)) | C12: =(US_BS!$G$8+US_BS!$G$6*$A12+US_BS!$G$10-(US_BS!$G$12+C$5+US_BS!$G$14+US_BS!$G$15)) | D12: =(US_BS!$G$8+US_BS!$G$6*$A12+US_BS!$G$10-(US_BS!$G$12+D$5+US_BS!$G$14+US_BS!$G$15)) | E12: =(US_BS!$G$8+US_BS!$G$6*$A12+US_BS!$G$10-(US_BS!$G$12+E$5+US_BS!$G$14+US_BS!$G$15)) | F12: =(US_BS!$G$8+US_BS!$G$6*$A12+US_BS!$G$10-(US_BS!$G$12+F$5+US_BS!$G$14+US_BS!$G$15)) | G12: =(US_BS!$G$8+US_BS!$G$6*$A12+US_BS!$G$10-(US_BS!$G$12+G$5+US_BS!$G$14+US_BS!$G$15))
A13: 54.5 | B13: =(US_BS!$G$8+US_BS!$G$6*$A13+US_BS!$G$10-(US_BS!$G$12+B$5+US_BS!$G$14+US_BS!$G$15)) | C13: =(US_BS!$G$8+US_BS!$G$6*$A13+US_BS!$G$10-(US_BS!$G$12+C$5+US_BS!$G$14+US_BS!$G$15)) | D13: =(US_BS!$G$8+US_BS!$G$6*$A13+US_BS!$G$10-(US_BS!$G$12+D$5+US_BS!$G$14+US_BS!$G$15)) | E13: =(US_BS!$G$8+US_BS!$G$6*$A13+US_BS!$G$10-(US_BS!$G$12+E$5+US_BS!$G$14+US_BS!$G$15)) | F13: =(US_BS!$G$8+US_BS!$G$6*$A13+US_BS!$G$10-(US_BS!$G$12+F$5+US_BS!$G$14+US_BS!$G$15)) | G13: =(US_BS!$G$8+US_BS!$G$6*$A13+US_BS!$G$10-(US_BS!$G$12+G$5+US_BS!$G$14+US_BS!$G$15))
A16: 2) Stocks / use
A17: Yield \ Exports (M bu) | B17: 1600 | C17: 1650 | D17: 1695 | E17: 1745 | F17: 1800 | G17: 1850
A18: 51.5 | B18: =(US_BS!$G$8+US_BS!$G$6*$A18+US_BS!$G$10-(US_BS!$G$12+B$17+US_BS!$G$14+US_BS!$G$15))/(US_BS!$G$12+B$17+US_BS!$G$14+US_BS!$G$15) | C18: =(US_BS!$G$8+US_BS!$G$6*$A18+US_BS!$G$10-(US_BS!$G$12+C$17+US_BS!$G$14+US_BS!$G$15))/(US_BS!$G$12+C$17+US_BS!$G$14+US_BS!$G$15) | D18: =(US_BS!$G$8+US_BS!$G$6*$A18+US_BS!$G$10-(US_BS!$G$12+D$17+US_BS!$G$14+US_BS!$G$15))/(US_BS!$G$12+D$17+US_BS!$G$14+US_BS!$G$15) | E18: =(US_BS!$G$8+US_BS!$G$6*$A18+US_BS!$G$10-(US_BS!$G$12+E$17+US_BS!$G$14+US_BS!$G$15))/(US_BS!$G$12+E$17+US_BS!$G$14+US_BS!$G$15) | F18: =(US_BS!$G$8+US_BS!$G$6*$A18+US_BS!$G$10-(US_BS!$G$12+F$17+US_BS!$G$14+US_BS!$G$15))/(US_BS!$G$12+F$17+US_BS!$G$14+US_BS!$G$15) | G18: =(US_BS!$G$8+US_BS!$G$6*$A18+US_BS!$G$10-(US_BS!$G$12+G$17+US_BS!$G$14+US_BS!$G$15))/(US_BS!$G$12+G$17+US_BS!$G$14+US_BS!$G$15)
A19: 52 | B19: =(US_BS!$G$8+US_BS!$G$6*$A19+US_BS!$G$10-(US_BS!$G$12+B$17+US_BS!$G$14+US_BS!$G$15))/(US_BS!$G$12+B$17+US_BS!$G$14+US_BS!$G$15) | C19: =(US_BS!$G$8+US_BS!$G$6*$A19+US_BS!$G$10-(US_BS!$G$12+C$17+US_BS!$G$14+US_BS!$G$15))/(US_BS!$G$12+C$17+US_BS!$G$14+US_BS!$G$15) | D19: =(US_BS!$G$8+US_BS!$G$6*$A19+US_BS!$G$10-(US_BS!$G$12+D$17+US_BS!$G$14+US_BS!$G$15))/(US_BS!$G$12+D$17+US_BS!$G$14+US_BS!$G$15) | E19: =(US_BS!$G$8+US_BS!$G$6*$A19+US_BS!$G$10-(US_BS!$G$12+E$17+US_BS!$G$14+US_BS!$G$15))/(US_BS!$G$12+E$17+US_BS!$G$14+US_BS!$G$15) | F19: =(US_BS!$G$8+US_BS!$G$6*$A19+US_BS!$G$10-(US_BS!$G$12+F$17+US_BS!$G$14+US_BS!$G$15))/(US_BS!$G$12+F$17+US_BS!$G$14+US_BS!$G$15) | G19: =(US_BS!$G$8+US_BS!$G$6*$A19+US_BS!$G$10-(US_BS!$G$12+G$17+US_BS!$G$14+US_BS!$G$15))/(US_BS!$G$12+G$17+US_BS!$G$14+US_BS!$G$15)
A20: 52.5 | B20: =(US_BS!$G$8+US_BS!$G$6*$A20+US_BS!$G$10-(US_BS!$G$12+B$17+US_BS!$G$14+US_BS!$G$15))/(US_BS!$G$12+B$17+US_BS!$G$14+US_BS!$G$15) | C20: =(US_BS!$G$8+US_BS!$G$6*$A20+US_BS!$G$10-(US_BS!$G$12+C$17+US_BS!$G$14+US_BS!$G$15))/(US_BS!$G$12+C$17+US_BS!$G$14+US_BS!$G$15) | D20: =(US_BS!$G$8+US_BS!$G$6*$A20+US_BS!$G$10-(US_BS!$G$12+D$17+US_BS!$G$14+US_BS!$G$15))/(US_BS!$G$12+D$17+US_BS!$G$14+US_BS!$G$15) | E20: =(US_BS!$G$8+US_BS!$G$6*$A20+US_BS!$G$10-(US_BS!$G$12+E$17+US_BS!$G$14+US_BS!$G$15))/(US_BS!$G$12+E$17+US_BS!$G$14+US_BS!$G$15) | F20: =(US_BS!$G$8+US_BS!$G$6*$A20+US_BS!$G$10-(US_BS!$G$12+F$17+US_BS!$G$14+US_BS!$G$15))/(US_BS!$G$12+F$17+US_BS!$G$14+US_BS!$G$15) | G20: =(US_BS!$G$8+US_BS!$G$6*$A20+US_BS!$G$10-(US_BS!$G$12+G$17+US_BS!$G$14+US_BS!$G$15))/(US_BS!$G$12+G$17+US_BS!$G$14+US_BS!$G$15)
A21: 52.9 | B21: =(US_BS!$G$8+US_BS!$G$6*$A21+US_BS!$G$10-(US_BS!$G$12+B$17+US_BS!$G$14+US_BS!$G$15))/(US_BS!$G$12+B$17+US_BS!$G$14+US_BS!$G$15) | C21: =(US_BS!$G$8+US_BS!$G$6*$A21+US_BS!$G$10-(US_BS!$G$12+C$17+US_BS!$G$14+US_BS!$G$15))/(US_BS!$G$12+C$17+US_BS!$G$14+US_BS!$G$15) | D21: =(US_BS!$G$8+US_BS!$G$6*$A21+US_BS!$G$10-(US_BS!$G$12+D$17+US_BS!$G$14+US_BS!$G$15))/(US_BS!$G$12+D$17+US_BS!$G$14+US_BS!$G$15) | E21: =(US_BS!$G$8+US_BS!$G$6*$A21+US_BS!$G$10-(US_BS!$G$12+E$17+US_BS!$G$14+US_BS!$G$15))/(US_BS!$G$12+E$17+US_BS!$G$14+US_BS!$G$15) | F21: =(US_BS!$G$8+US_BS!$G$6*$A21+US_BS!$G$10-(US_BS!$G$12+F$17+US_BS!$G$14+US_BS!$G$15))/(US_BS!$G$12+F$17+US_BS!$G$14+US_BS!$G$15) | G21: =(US_BS!$G$8+US_BS!$G$6*$A21+US_BS!$G$10-(US_BS!$G$12+G$17+US_BS!$G$14+US_BS!$G$15))/(US_BS!$G$12+G$17+US_BS!$G$14+US_BS!$G$15)
A22: 53.1 | B22: =(US_BS!$G$8+US_BS!$G$6*$A22+US_BS!$G$10-(US_BS!$G$12+B$17+US_BS!$G$14+US_BS!$G$15))/(US_BS!$G$12+B$17+US_BS!$G$14+US_BS!$G$15) | C22: =(US_BS!$G$8+US_BS!$G$6*$A22+US_BS!$G$10-(US_BS!$G$12+C$17+US_BS!$G$14+US_BS!$G$15))/(US_BS!$G$12+C$17+US_BS!$G$14+US_BS!$G$15) | D22: =(US_BS!$G$8+US_BS!$G$6*$A22+US_BS!$G$10-(US_BS!$G$12+D$17+US_BS!$G$14+US_BS!$G$15))/(US_BS!$G$12+D$17+US_BS!$G$14+US_BS!$G$15) | E22: =(US_BS!$G$8+US_BS!$G$6*$A22+US_BS!$G$10-(US_BS!$G$12+E$17+US_BS!$G$14+US_BS!$G$15))/(US_BS!$G$12+E$17+US_BS!$G$14+US_BS!$G$15) | F22: =(US_BS!$G$8+US_BS!$G$6*$A22+US_BS!$G$10-(US_BS!$G$12+F$17+US_BS!$G$14+US_BS!$G$15))/(US_BS!$G$12+F$17+US_BS!$G$14+US_BS!$G$15) | G22: =(US_BS!$G$8+US_BS!$G$6*$A22+US_BS!$G$10-(US_BS!$G$12+G$17+US_BS!$G$14+US_BS!$G$15))/(US_BS!$G$12+G$17+US_BS!$G$14+US_BS!$G$15)
A23: 53.5 | B23: =(US_BS!$G$8+US_BS!$G$6*$A23+US_BS!$G$10-(US_BS!$G$12+B$17+US_BS!$G$14+US_BS!$G$15))/(US_BS!$G$12+B$17+US_BS!$G$14+US_BS!$G$15) | C23: =(US_BS!$G$8+US_BS!$G$6*$A23+US_BS!$G$10-(US_BS!$G$12+C$17+US_BS!$G$14+US_BS!$G$15))/(US_BS!$G$12+C$17+US_BS!$G$14+US_BS!$G$15) | D23: =(US_BS!$G$8+US_BS!$G$6*$A23+US_BS!$G$10-(US_BS!$G$12+D$17+US_BS!$G$14+US_BS!$G$15))/(US_BS!$G$12+D$17+US_BS!$G$14+US_BS!$G$15) | E23: =(US_BS!$G$8+US_BS!$G$6*$A23+US_BS!$G$10-(US_BS!$G$12+E$17+US_BS!$G$14+US_BS!$G$15))/(US_BS!$G$12+E$17+US_BS!$G$14+US_BS!$G$15) | F23: =(US_BS!$G$8+US_BS!$G$6*$A23+US_BS!$G$10-(US_BS!$G$12+F$17+US_BS!$G$14+US_BS!$G$15))/(US_BS!$G$12+F$17+US_BS!$G$14+US_BS!$G$15) | G23: =(US_BS!$G$8+US_BS!$G$6*$A23+US_BS!$G$10-(US_BS!$G$12+G$17+US_BS!$G$14+US_BS!$G$15))/(US_BS!$G$12+G$17+US_BS!$G$14+US_BS!$G$15)
A24: 54 | B24: =(US_BS!$G$8+US_BS!$G$6*$A24+US_BS!$G$10-(US_BS!$G$12+B$17+US_BS!$G$14+US_BS!$G$15))/(US_BS!$G$12+B$17+US_BS!$G$14+US_BS!$G$15) | C24: =(US_BS!$G$8+US_BS!$G$6*$A24+US_BS!$G$10-(US_BS!$G$12+C$17+US_BS!$G$14+US_BS!$G$15))/(US_BS!$G$12+C$17+US_BS!$G$14+US_BS!$G$15) | D24: =(US_BS!$G$8+US_BS!$G$6*$A24+US_BS!$G$10-(US_BS!$G$12+D$17+US_BS!$G$14+US_BS!$G$15))/(US_BS!$G$12+D$17+US_BS!$G$14+US_BS!$G$15) | E24: =(US_BS!$G$8+US_BS!$G$6*$A24+US_BS!$G$10-(US_BS!$G$12+E$17+US_BS!$G$14+US_BS!$G$15))/(US_BS!$G$12+E$17+US_BS!$G$14+US_BS!$G$15) | F24: =(US_BS!$G$8+US_BS!$G$6*$A24+US_BS!$G$10-(US_BS!$G$12+F$17+US_BS!$G$14+US_BS!$G$15))/(US_BS!$G$12+F$17+US_BS!$G$14+US_BS!$G$15) | G24: =(US_BS!$G$8+US_BS!$G$6*$A24+US_BS!$G$10-(US_BS!$G$12+G$17+US_BS!$G$14+US_BS!$G$15))/(US_BS!$G$12+G$17+US_BS!$G$14+US_BS!$G$15)
A25: 54.5 | B25: =(US_BS!$G$8+US_BS!$G$6*$A25+US_BS!$G$10-(US_BS!$G$12+B$17+US_BS!$G$14+US_BS!$G$15))/(US_BS!$G$12+B$17+US_BS!$G$14+US_BS!$G$15) | C25: =(US_BS!$G$8+US_BS!$G$6*$A25+US_BS!$G$10-(US_BS!$G$12+C$17+US_BS!$G$14+US_BS!$G$15))/(US_BS!$G$12+C$17+US_BS!$G$14+US_BS!$G$15) | D25: =(US_BS!$G$8+US_BS!$G$6*$A25+US_BS!$G$10-(US_BS!$G$12+D$17+US_BS!$G$14+US_BS!$G$15))/(US_BS!$G$12+D$17+US_BS!$G$14+US_BS!$G$15) | E25: =(US_BS!$G$8+US_BS!$G$6*$A25+US_BS!$G$10-(US_BS!$G$12+E$17+US_BS!$G$14+US_BS!$G$15))/(US_BS!$G$12+E$17+US_BS!$G$14+US_BS!$G$15) | F25: =(US_BS!$G$8+US_BS!$G$6*$A25+US_BS!$G$10-(US_BS!$G$12+F$17+US_BS!$G$14+US_BS!$G$15))/(US_BS!$G$12+F$17+US_BS!$G$14+US_BS!$G$15) | G25: =(US_BS!$G$8+US_BS!$G$6*$A25+US_BS!$G$10-(US_BS!$G$12+G$17+US_BS!$G$14+US_BS!$G$15))/(US_BS!$G$12+G$17+US_BS!$G$14+US_BS!$G$15)
A28: 3) Implied SAFP ($/bu) - Price_Model regression (floor S/U 0.5%)
A29: Yield \ Exports (M bu) | B29: 1600 | C29: 1650 | D29: 1695 | E29: 1745 | F29: 1800 | G29: 1850
A30: 51.5 | B30: =Price_Model!$C$23+Price_Model!$C$22*LN(MAX(0.005,(US_BS!$G$8+US_BS!$G$6*$A30+US_BS!$G$10-(US_BS!$G$12+B$29+US_BS!$G$14+US_BS!$G$15))/(US_BS!$G$12+B$29+US_BS!$G$14+US_BS!$G$15))) | C30: =Price_Model!$C$23+Price_Model!$C$22*LN(MAX(0.005,(US_BS!$G$8+US_BS!$G$6*$A30+US_BS!$G$10-(US_BS!$G$12+C$29+US_BS!$G$14+US_BS!$G$15))/(US_BS!$G$12+C$29+US_BS!$G$14+US_BS!$G$15))) | D30: =Price_Model!$C$23+Price_Model!$C$22*LN(MAX(0.005,(US_BS!$G$8+US_BS!$G$6*$A30+US_BS!$G$10-(US_BS!$G$12+D$29+US_BS!$G$14+US_BS!$G$15))/(US_BS!$G$12+D$29+US_BS!$G$14+US_BS!$G$15))) | E30: =Price_Model!$C$23+Price_Model!$C$22*LN(MAX(0.005,(US_BS!$G$8+US_BS!$G$6*$A30+US_BS!$G$10-(US_BS!$G$12+E$29+US_BS!$G$14+US_BS!$G$15))/(US_BS!$G$12+E$29+US_BS!$G$14+US_BS!$G$15))) | F30: =Price_Model!$C$23+Price_Model!$C$22*LN(MAX(0.005,(US_BS!$G$8+US_BS!$G$6*$A30+US_BS!$G$10-(US_BS!$G$12+F$29+US_BS!$G$14+US_BS!$G$15))/(US_BS!$G$12+F$29+US_BS!$G$14+US_BS!$G$15))) | G30: =Price_Model!$C$23+Price_Model!$C$22*LN(MAX(0.005,(US_BS!$G$8+US_BS!$G$6*$A30+US_BS!$G$10-(US_BS!$G$12+G$29+US_BS!$G$14+US_BS!$G$15))/(US_BS!$G$12+G$29+US_BS!$G$14+US_BS!$G$15)))
A31: 52 | B31: =Price_Model!$C$23+Price_Model!$C$22*LN(MAX(0.005,(US_BS!$G$8+US_BS!$G$6*$A31+US_BS!$G$10-(US_BS!$G$12+B$29+US_BS!$G$14+US_BS!$G$15))/(US_BS!$G$12+B$29+US_BS!$G$14+US_BS!$G$15))) | C31: =Price_Model!$C$23+Price_Model!$C$22*LN(MAX(0.005,(US_BS!$G$8+US_BS!$G$6*$A31+US_BS!$G$10-(US_BS!$G$12+C$29+US_BS!$G$14+US_BS!$G$15))/(US_BS!$G$12+C$29+US_BS!$G$14+US_BS!$G$15))) | D31: =Price_Model!$C$23+Price_Model!$C$22*LN(MAX(0.005,(US_BS!$G$8+US_BS!$G$6*$A31+US_BS!$G$10-(US_BS!$G$12+D$29+US_BS!$G$14+US_BS!$G$15))/(US_BS!$G$12+D$29+US_BS!$G$14+US_BS!$G$15))) | E31: =Price_Model!$C$23+Price_Model!$C$22*LN(MAX(0.005,(US_BS!$G$8+US_BS!$G$6*$A31+US_BS!$G$10-(US_BS!$G$12+E$29+US_BS!$G$14+US_BS!$G$15))/(US_BS!$G$12+E$29+US_BS!$G$14+US_BS!$G$15))) | F31: =Price_Model!$C$23+Price_Model!$C$22*LN(MAX(0.005,(US_BS!$G$8+US_BS!$G$6*$A31+US_BS!$G$10-(US_BS!$G$12+F$29+US_BS!$G$14+US_BS!$G$15))/(US_BS!$G$12+F$29+US_BS!$G$14+US_BS!$G$15))) | G31: =Price_Model!$C$23+Price_Model!$C$22*LN(MAX(0.005,(US_BS!$G$8+US_BS!$G$6*$A31+US_BS!$G$10-(US_BS!$G$12+G$29+US_BS!$G$14+US_BS!$G$15))/(US_BS!$G$12+G$29+US_BS!$G$14+US_BS!$G$15)))
A32: 52.5 | B32: =Price_Model!$C$23+Price_Model!$C$22*LN(MAX(0.005,(US_BS!$G$8+US_BS!$G$6*$A32+US_BS!$G$10-(US_BS!$G$12+B$29+US_BS!$G$14+US_BS!$G$15))/(US_BS!$G$12+B$29+US_BS!$G$14+US_BS!$G$15))) | C32: =Price_Model!$C$23+Price_Model!$C$22*LN(MAX(0.005,(US_BS!$G$8+US_BS!$G$6*$A32+US_BS!$G$10-(US_BS!$G$12+C$29+US_BS!$G$14+US_BS!$G$15))/(US_BS!$G$12+C$29+US_BS!$G$14+US_BS!$G$15))) | D32: =Price_Model!$C$23+Price_Model!$C$22*LN(MAX(0.005,(US_BS!$G$8+US_BS!$G$6*$A32+US_BS!$G$10-(US_BS!$G$12+D$29+US_BS!$G$14+US_BS!$G$15))/(US_BS!$G$12+D$29+US_BS!$G$14+US_BS!$G$15))) | E32: =Price_Model!$C$23+Price_Model!$C$22*LN(MAX(0.005,(US_BS!$G$8+US_BS!$G$6*$A32+US_BS!$G$10-(US_BS!$G$12+E$29+US_BS!$G$14+US_BS!$G$15))/(US_BS!$G$12+E$29+US_BS!$G$14+US_BS!$G$15))) | F32: =Price_Model!$C$23+Price_Model!$C$22*LN(MAX(0.005,(US_BS!$G$8+US_BS!$G$6*$A32+US_BS!$G$10-(US_BS!$G$12+F$29+US_BS!$G$14+US_BS!$G$15))/(US_BS!$G$12+F$29+US_BS!$G$14+US_BS!$G$15))) | G32: =Price_Model!$C$23+Price_Model!$C$22*LN(MAX(0.005,(US_BS!$G$8+US_BS!$G$6*$A32+US_BS!$G$10-(US_BS!$G$12+G$29+US_BS!$G$14+US_BS!$G$15))/(US_BS!$G$12+G$29+US_BS!$G$14+US_BS!$G$15)))
A33: 52.9 | B33: =Price_Model!$C$23+Price_Model!$C$22*LN(MAX(0.005,(US_BS!$G$8+US_BS!$G$6*$A33+US_BS!$G$10-(US_BS!$G$12+B$29+US_BS!$G$14+US_BS!$G$15))/(US_BS!$G$12+B$29+US_BS!$G$14+US_BS!$G$15))) | C33: =Price_Model!$C$23+Price_Model!$C$22*LN(MAX(0.005,(US_BS!$G$8+US_BS!$G$6*$A33+US_BS!$G$10-(US_BS!$G$12+C$29+US_BS!$G$14+US_BS!$G$15))/(US_BS!$G$12+C$29+US_BS!$G$14+US_BS!$G$15))) | D33: =Price_Model!$C$23+Price_Model!$C$22*LN(MAX(0.005,(US_BS!$G$8+US_BS!$G$6*$A33+US_BS!$G$10-(US_BS!$G$12+D$29+US_BS!$G$14+US_BS!$G$15))/(US_BS!$G$12+D$29+US_BS!$G$14+US_BS!$G$15))) | E33: =Price_Model!$C$23+Price_Model!$C$22*LN(MAX(0.005,(US_BS!$G$8+US_BS!$G$6*$A33+US_BS!$G$10-(US_BS!$G$12+E$29+US_BS!$G$14+US_BS!$G$15))/(US_BS!$G$12+E$29+US_BS!$G$14+US_BS!$G$15))) | F33: =Price_Model!$C$23+Price_Model!$C$22*LN(MAX(0.005,(US_BS!$G$8+US_BS!$G$6*$A33+US_BS!$G$10-(US_BS!$G$12+F$29+US_BS!$G$14+US_BS!$G$15))/(US_BS!$G$12+F$29+US_BS!$G$14+US_BS!$G$15))) | G33: =Price_Model!$C$23+Price_Model!$C$22*LN(MAX(0.005,(US_BS!$G$8+US_BS!$G$6*$A33+US_BS!$G$10-(US_BS!$G$12+G$29+US_BS!$G$14+US_BS!$G$15))/(US_BS!$G$12+G$29+US_BS!$G$14+US_BS!$G$15)))
A34: 53.1 | B34: =Price_Model!$C$23+Price_Model!$C$22*LN(MAX(0.005,(US_BS!$G$8+US_BS!$G$6*$A34+US_BS!$G$10-(US_BS!$G$12+B$29+US_BS!$G$14+US_BS!$G$15))/(US_BS!$G$12+B$29+US_BS!$G$14+US_BS!$G$15))) | C34: =Price_Model!$C$23+Price_Model!$C$22*LN(MAX(0.005,(US_BS!$G$8+US_BS!$G$6*$A34+US_BS!$G$10-(US_BS!$G$12+C$29+US_BS!$G$14+US_BS!$G$15))/(US_BS!$G$12+C$29+US_BS!$G$14+US_BS!$G$15))) | D34: =Price_Model!$C$23+Price_Model!$C$22*LN(MAX(0.005,(US_BS!$G$8+US_BS!$G$6*$A34+US_BS!$G$10-(US_BS!$G$12+D$29+US_BS!$G$14+US_BS!$G$15))/(US_BS!$G$12+D$29+US_BS!$G$14+US_BS!$G$15))) | E34: =Price_Model!$C$23+Price_Model!$C$22*LN(MAX(0.005,(US_BS!$G$8+US_BS!$G$6*$A34+US_BS!$G$10-(US_BS!$G$12+E$29+US_BS!$G$14+US_BS!$G$15))/(US_BS!$G$12+E$29+US_BS!$G$14+US_BS!$G$15))) | F34: =Price_Model!$C$23+Price_Model!$C$22*LN(MAX(0.005,(US_BS!$G$8+US_BS!$G$6*$A34+US_BS!$G$10-(US_BS!$G$12+F$29+US_BS!$G$14+US_BS!$G$15))/(US_BS!$G$12+F$29+US_BS!$G$14+US_BS!$G$15))) | G34: =Price_Model!$C$23+Price_Model!$C$22*LN(MAX(0.005,(US_BS!$G$8+US_BS!$G$6*$A34+US_BS!$G$10-(US_BS!$G$12+G$29+US_BS!$G$14+US_BS!$G$15))/(US_BS!$G$12+G$29+US_BS!$G$14+US_BS!$G$15)))
A35: 53.5 | B35: =Price_Model!$C$23+Price_Model!$C$22*LN(MAX(0.005,(US_BS!$G$8+US_BS!$G$6*$A35+US_BS!$G$10-(US_BS!$G$12+B$29+US_BS!$G$14+US_BS!$G$15))/(US_BS!$G$12+B$29+US_BS!$G$14+US_BS!$G$15))) | C35: =Price_Model!$C$23+Price_Model!$C$22*LN(MAX(0.005,(US_BS!$G$8+US_BS!$G$6*$A35+US_BS!$G$10-(US_BS!$G$12+C$29+US_BS!$G$14+US_BS!$G$15))/(US_BS!$G$12+C$29+US_BS!$G$14+US_BS!$G$15))) | D35: =Price_Model!$C$23+Price_Model!$C$22*LN(MAX(0.005,(US_BS!$G$8+US_BS!$G$6*$A35+US_BS!$G$10-(US_BS!$G$12+D$29+US_BS!$G$14+US_BS!$G$15))/(US_BS!$G$12+D$29+US_BS!$G$14+US_BS!$G$15))) | E35: =Price_Model!$C$23+Price_Model!$C$22*LN(MAX(0.005,(US_BS!$G$8+US_BS!$G$6*$A35+US_BS!$G$10-(US_BS!$G$12+E$29+US_BS!$G$14+US_BS!$G$15))/(US_BS!$G$12+E$29+US_BS!$G$14+US_BS!$G$15))) | F35: =Price_Model!$C$23+Price_Model!$C$22*LN(MAX(0.005,(US_BS!$G$8+US_BS!$G$6*$A35+US_BS!$G$10-(US_BS!$G$12+F$29+US_BS!$G$14+US_BS!$G$15))/(US_BS!$G$12+F$29+US_BS!$G$14+US_BS!$G$15))) | G35: =Price_Model!$C$23+Price_Model!$C$22*LN(MAX(0.005,(US_BS!$G$8+US_BS!$G$6*$A35+US_BS!$G$10-(US_BS!$G$12+G$29+US_BS!$G$14+US_BS!$G$15))/(US_BS!$G$12+G$29+US_BS!$G$14+US_BS!$G$15)))
A36: 54 | B36: =Price_Model!$C$23+Price_Model!$C$22*LN(MAX(0.005,(US_BS!$G$8+US_BS!$G$6*$A36+US_BS!$G$10-(US_BS!$G$12+B$29+US_BS!$G$14+US_BS!$G$15))/(US_BS!$G$12+B$29+US_BS!$G$14+US_BS!$G$15))) | C36: =Price_Model!$C$23+Price_Model!$C$22*LN(MAX(0.005,(US_BS!$G$8+US_BS!$G$6*$A36+US_BS!$G$10-(US_BS!$G$12+C$29+US_BS!$G$14+US_BS!$G$15))/(US_BS!$G$12+C$29+US_BS!$G$14+US_BS!$G$15))) | D36: =Price_Model!$C$23+Price_Model!$C$22*LN(MAX(0.005,(US_BS!$G$8+US_BS!$G$6*$A36+US_BS!$G$10-(US_BS!$G$12+D$29+US_BS!$G$14+US_BS!$G$15))/(US_BS!$G$12+D$29+US_BS!$G$14+US_BS!$G$15))) | E36: =Price_Model!$C$23+Price_Model!$C$22*LN(MAX(0.005,(US_BS!$G$8+US_BS!$G$6*$A36+US_BS!$G$10-(US_BS!$G$12+E$29+US_BS!$G$14+US_BS!$G$15))/(US_BS!$G$12+E$29+US_BS!$G$14+US_BS!$G$15))) | F36: =Price_Model!$C$23+Price_Model!$C$22*LN(MAX(0.005,(US_BS!$G$8+US_BS!$G$6*$A36+US_BS!$G$10-(US_BS!$G$12+F$29+US_BS!$G$14+US_BS!$G$15))/(US_BS!$G$12+F$29+US_BS!$G$14+US_BS!$G$15))) | G36: =Price_Model!$C$23+Price_Model!$C$22*LN(MAX(0.005,(US_BS!$G$8+US_BS!$G$6*$A36+US_BS!$G$10-(US_BS!$G$12+G$29+US_BS!$G$14+US_BS!$G$15))/(US_BS!$G$12+G$29+US_BS!$G$14+US_BS!$G$15)))
A37: 54.5 | B37: =Price_Model!$C$23+Price_Model!$C$22*LN(MAX(0.005,(US_BS!$G$8+US_BS!$G$6*$A37+US_BS!$G$10-(US_BS!$G$12+B$29+US_BS!$G$14+US_BS!$G$15))/(US_BS!$G$12+B$29+US_BS!$G$14+US_BS!$G$15))) | C37: =Price_Model!$C$23+Price_Model!$C$22*LN(MAX(0.005,(US_BS!$G$8+US_BS!$G$6*$A37+US_BS!$G$10-(US_BS!$G$12+C$29+US_BS!$G$14+US_BS!$G$15))/(US_BS!$G$12+C$29+US_BS!$G$14+US_BS!$G$15))) | D37: =Price_Model!$C$23+Price_Model!$C$22*LN(MAX(0.005,(US_BS!$G$8+US_BS!$G$6*$A37+US_BS!$G$10-(US_BS!$G$12+D$29+US_BS!$G$14+US_BS!$G$15))/(US_BS!$G$12+D$29+US_BS!$G$14+US_BS!$G$15))) | E37: =Price_Model!$C$23+Price_Model!$C$22*LN(MAX(0.005,(US_BS!$G$8+US_BS!$G$6*$A37+US_BS!$G$10-(US_BS!$G$12+E$29+US_BS!$G$14+US_BS!$G$15))/(US_BS!$G$12+E$29+US_BS!$G$14+US_BS!$G$15))) | F37: =Price_Model!$C$23+Price_Model!$C$22*LN(MAX(0.005,(US_BS!$G$8+US_BS!$G$6*$A37+US_BS!$G$10-(US_BS!$G$12+F$29+US_BS!$G$14+US_BS!$G$15))/(US_BS!$G$12+F$29+US_BS!$G$14+US_BS!$G$15))) | G37: =Price_Model!$C$23+Price_Model!$C$22*LN(MAX(0.005,(US_BS!$G$8+US_BS!$G$6*$A37+US_BS!$G$10-(US_BS!$G$12+G$29+US_BS!$G$14+US_BS!$G$15))/(US_BS!$G$12+G$29+US_BS!$G$14+US_BS!$G$15)))
A39: USDA Oct = 53.1 bpa / 1,695 mb exports. House = 52.9 / 1,745. Sensitivity: 1 bpa ~ 86 mb; 50 mb exports ~ 1.1 pts S/U.

Sheet Crush
A1: BOARD CRUSH MARGIN
A2: Board crush = meal x 44/2000 + oil x 11/100 - soybeans. Products Dec-26 vs beans Nov-26 (update prices on Inputs).
A4: Soybean meal ($/short ton) | B4: =Inputs!$B$26
A5: Meal yield (lb/bu) | B5: =Inputs!$B$33
A6: Meal value ($/bu) | B6: =B4*B5/2000
A7: Soybean oil (c/lb) | B7: =Inputs!$B$27
A8: Oil yield (lb/bu) | B8: =Inputs!$B$34
A9: Oil value ($/bu) | B9: =B7*B8/100
A10: Gross product value ($/bu) | B10: =B6+B9
A11: Soybeans Nov-26 ($/bu) | B11: =Inputs!$B$23/100
A12: BOARD CRUSH MARGIN ($/bu) | B12: =B10-B11 | C12: Reference: ~$1.00-1.50/bu typical; >$2.00 = strong incentive to run plants at capacity (supports House crush +40 mb).
A13: Oil share of product value | B13: =B9/B10
A16: Sensitivity: margin ($/bu) - rows oil (c/lb), columns meal ($/st); beans at Inputs
A17: Oil \ Meal | B17: 320 | C17: 335 | D17: 350 | E17: 355 | F17: 365 | G17: 380
A18: 60 | B18: =B$17*$B$5/2000+$A18*$B$8/100-$B$11 | C18: =C$17*$B$5/2000+$A18*$B$8/100-$B$11 | D18: =D$17*$B$5/2000+$A18*$B$8/100-$B$11 | E18: =E$17*$B$5/2000+$A18*$B$8/100-$B$11 | F18: =F$17*$B$5/2000+$A18*$B$8/100-$B$11 | G18: =G$17*$B$5/2000+$A18*$B$8/100-$B$11
A19: 64 | B19: =B$17*$B$5/2000+$A19*$B$8/100-$B$11 | C19: =C$17*$B$5/2000+$A19*$B$8/100-$B$11 | D19: =D$17*$B$5/2000+$A19*$B$8/100-$B$11 | E19: =E$17*$B$5/2000+$A19*$B$8/100-$B$11 | F19: =F$17*$B$5/2000+$A19*$B$8/100-$B$11 | G19: =G$17*$B$5/2000+$A19*$B$8/100-$B$11
A20: 68 | B20: =B$17*$B$5/2000+$A20*$B$8/100-$B$11 | C20: =C$17*$B$5/2000+$A20*$B$8/100-$B$11 | D20: =D$17*$B$5/2000+$A20*$B$8/100-$B$11 | E20: =E$17*$B$5/2000+$A20*$B$8/100-$B$11 | F20: =F$17*$B$5/2000+$A20*$B$8/100-$B$11 | G20: =G$17*$B$5/2000+$A20*$B$8/100-$B$11
A21: 70 | B21: =B$17*$B$5/2000+$A21*$B$8/100-$B$11 | C21: =C$17*$B$5/2000+$A21*$B$8/100-$B$11 | D21: =D$17*$B$5/2000+$A21*$B$8/100-$B$11 | E21: =E$17*$B$5/2000+$A21*$B$8/100-$B$11 | F21: =F$17*$B$5/2000+$A21*$B$8/100-$B$11 | G21: =G$17*$B$5/2000+$A21*$B$8/100-$B$11
A22: 72 | B22: =B$17*$B$5/2000+$A22*$B$8/100-$B$11 | C22: =C$17*$B$5/2000+$A22*$B$8/100-$B$11 | D22: =D$17*$B$5/2000+$A22*$B$8/100-$B$11 | E22: =E$17*$B$5/2000+$A22*$B$8/100-$B$11 | F22: =F$17*$B$5/2000+$A22*$B$8/100-$B$11 | G22: =G$17*$B$5/2000+$A22*$B$8/100-$B$11
A23: 76 | B23: =B$17*$B$5/2000+$A23*$B$8/100-$B$11 | C23: =C$17*$B$5/2000+$A23*$B$8/100-$B$11 | D23: =D$17*$B$5/2000+$A23*$B$8/100-$B$11 | E23: =E$17*$B$5/2000+$A23*$B$8/100-$B$11 | F23: =F$17*$B$5/2000+$A23*$B$8/100-$B$11 | G23: =G$17*$B$5/2000+$A23*$B$8/100-$B$11
A24: 80 | B24: =B$17*$B$5/2000+$A24*$B$8/100-$B$11 | C24: =C$17*$B$5/2000+$A24*$B$8/100-$B$11 | D24: =D$17*$B$5/2000+$A24*$B$8/100-$B$11 | E24: =E$17*$B$5/2000+$A24*$B$8/100-$B$11 | F24: =F$17*$B$5/2000+$A24*$B$8/100-$B$11 | G24: =G$17*$B$5/2000+$A24*$B$8/100-$B$11

Sheet Spreads
A1: CALENDAR SPREADS vs FULL CARRY + OLD/NEW-CROP BULL SPREAD
A2: Full carry = storage x days + financing on front-month value. % of full carry near 100% = ample stocks; falling % / inversion = tightness.
A4: Spread | B4: Front (c/bu) | C4: Back (c/bu) | D4: Spread back-front (c) | E4: Days | F4: Storage (c) | G4: Financing (c) | H4: Full carry (c) | I4: % of full carry
A5: Nov-26 / Jan-27 | B5: =Inputs!$B$23 | C5: =Inputs!$B$24 | D5: =C5-B5 | E5: =Inputs!$B$30 | F5: =Inputs!$B$28*E5 | G5: =B5*Inputs!$B$29*E5/365 | H5: =F5+G5 | I5: =IF(H5=0,0,D5/H5)
A6: Jan-27 / Mar-27 | B6: =Inputs!$B$24 | C6: =Inputs!$B$25 | D6: =C6-B6 | E6: =Inputs!$B$31 | F6: =Inputs!$B$28*E6 | G6: =B6*Inputs!$B$29*E6/365 | H6: =F6+G6 | I6: =IF(H6=0,0,D6/H6)
A9: Read: % of full carry near 100% = ample stocks; a falling % or an inversion signals nearby tightness. House S/U ~4.5% (vs USDA 6.9%) would be consistent with the post-harvest carry narrowing.

Sheet Sources
A1: SOURCES & UPDATE CALENDAR
A2: IDs referenced in Inputs / sheet notes as [Sx].
A4: ID | B4: Source | C4: Used for | D4: Date / vintage | E4: Link
A5: S1 | B5: USDA WAOB - WASDE No. 676 | C5: US soybean balance sheet (Sep & Oct-26), products | D5: 9-Oct-2026 | E5: https://www.usda.gov/oce/commodity/wasde/wasde1026.pdf
A6: S2 | B6: USDA FAS - Oilseeds: World Markets and Trade | C6: World & country soybean S&D (Table 07, Table 16) | D6: Oct-2026 | E6: https://apps.fas.usda.gov/psdonline/circulars/oilseeds.pdf
A7: S3 | B7: USDA NASS - Grain Stocks | C7: Sep-1-2026 soybean stocks 315 mb | D7: 30-Sep-2026 | E7: https://www.dtnpf.com/agriculture/web/ag/news/article/2026/09/30/usda-releases-quarterly-grain-stocks-2
A8: S4 | B8: Brownfield Ag News - closing futures | C8: Settles: soybeans, meal, oil (6-Oct-26) | D8: 6-Oct-2026 | E8: https://www.brownfieldagnews.com/market-news/closing-grain-and-livestock-futures-october-6-2026/
A9: S5 | B9: USDA NASS - Fats & Oils (Aug crush 209.6 mb) | C9: Crush pace | D9: 1-Oct-2026 | E9: https://www.totalfarmmarketing.com/tfm-daily-market-summary-10-2-2026/
A10: S6 | B10: Pro Farmer - October WASDE preview (Reuters poll) | C10: Trade yield expectations 52.9 (51.4-54.1) | D10: Oct-2026 | E10: https://profarmer.com/news/agriculture-news/october-wasde-preview-key-metrics-watch-corn-soybeans-wheat-and-cotton
A11: S7 | B11: USDA FAS - Export Sales / Farm Progress | C11: Commitments +89% y/y; 10.76 MMT outstanding to China | D11: Oct-2026 | E11: https://www.farmprogress.com/markets-and-quotes/morning-market-review
A12: S8 | B12: CONAB via Nasdaq/Barchart | C12: Brazil 2026/27 first estimate 181.64 MMT | D12: Sep-2026 | E12: https://www.nasdaq.com/articles/soybeans-posting-gains-meal-rallies
A13: S9 | B13: USDA conversion factors | C13: 36.7437 bu per MT soybeans | D13: Standard | E13: https://www.ers.usda.gov/data-products/oil-crops-yearbook
A14: S10 | B14: CropGPT summary of USDA vs CASDE | C14: China imports CASDE 95.5 MMT (May-26) | D14: May-2026 | E14: https://cropgpt.ai/usda-lifts-2026-27-global-soybean-supply-outlook-as-brazil-u-s-argentina-boost-output-exports-up-china-demand-uncertain
A15: S11 | B15: CME Fed Funds / SOFR futures (CQG) | C15: Financing-rate assumption | D15: 6-Oct-2026 | E15: CQG: ZQEV26 96.1175 / SR1V26 96.105
... A17: S13 | B17: USDA FAS PSD Online | C17: VERIFY historical total use & SAFP (approximations) | D17: - | E17: https://apps.fas.usda.gov/psdonline/
A20: UPDATE CALENDAR
A21: Release | B21: Frequency | C21: Updates | D21: Next (approx.)
A22: USDA WASDE / Crop Production | B22: Monthly | C22: US_BS cols, World_BS USDA blocks | D22: 10-Nov-2026
A23: USDA Export Sales | B23: Weekly (Thu) | C23: Inputs: Exports (pace vs USDA) | D23: Every Thursday
A24: NOPA crush | B24: Monthly (~15th) | C24: Inputs: Crush | D24: 15-Oct-2026
A25: USDA Crop Progress | B25: Weekly (Mon) | C25: Yield model condition adj. | D25: Every Monday
A26: USDA Grain Stocks | B26: Quarterly | C26: Beginning stocks / residual check | D26: Jan-2027
A27: CONAB (Brazil) | B27: Monthly | C27: Inputs: Brazil production | D27: Mid-month
A28: CFTC Commitments of Traders | B28: Weekly (Fri) | C28: Positioning overlay (not in model) | D28: Every Friday
A29: CQG prices | B29: Daily | C29: Inputs: market block | D29: Daily
